Workbook

Sheet TEAM MAP
A1: TEAM MAP / ALIASES — do not edit without a CHANGELOG entry
A2: Master list (A:F) · MANUAL alias table (H:I, used by MARKET LINES + ADJUSTMENTS; ambiguous shorthand excluded) · IMPORT alias table (K:L, used by CLEAN; CFBD canonical names resolve here) · FBS conference strings (N) · Blocked manual shorthand (Q)
A5: Abbrev | H5: MANUAL alias | J5: Alias diagnostic (auto) | K5: IMPORT alias
A6: ALA | H6: ALA | J6: =IF($H6="","",IF(SUMPRODUCT(--(LOWER(TRIM($H$6:$H$481))=LOWER(TRIM($H6))),--($I$6:$I$481<>$I6))>0,"AMBIGUOUS — MAPS TO MULTIPLE TEAMS",IF(COUNTIF($H$6:$H$481,$H6)>1,"DUPLICATE x"&COUNTIF($H$6:$H$481,$H6)&" -> "&$I6,""))) | K6: Alabama
A7: ARK | H7: Alabama | J7: =IF($H7="","",IF(SUMPRODUCT(--(LOWER(TRIM($H$6:$H$481))=LOWER(TRIM($H7))),--($I$6:$I$481<>$I7))>0,"AMBIGUOUS — MAPS TO MULTIPLE TEAMS",IF(COUNTIF($H$6:$H$481,$H7)>1,"DUPLICATE x"&COUNTIF($H$6:$H$481,$H7)&" -> "&$I7,""))) | K7: ALA
A8: AUB | H8: Bama | J8: =IF($H8="","",IF(SUMPRODUCT(--(LOWER(TRIM($H$6:$H$481))=LOWER(TRIM($H8))),--($I$6:$I$481<>$I8))>0,"AMBIGUOUS — MAPS TO MULTIPLE TEAMS",IF(COUNTIF($H$6:$H$481,$H8)>1,"DUPLICATE x"&COUNTIF($H$6:$H$481,$H8)&" -> "&$I8,""))) | K8: Arkansas
A9: FLA | H9: Crimson Tide | J9: =IF($H9="","",IF(SUMPRODUCT(--(LOWER(TRIM($H$6:$H$481))=LOWER(TRIM($H9))),--($I$6:$I$481<>$I9))>0,"AMBIGUOUS — MAPS TO MULTIPLE TEAMS",IF(COUNTIF($H$6:$H$481,$H9)>1,"DUPLICATE x"&COUNTIF($H$6:$H$481,$H9)&" -> "&$I9,""))) | K9: ARK
A10: UGA | H10: ARK | J10: =IF($H10="","",IF(SUMPRODUCT(--(LOWER(TRIM($H$6:$H$481))=LOWER(TRIM($H10))),--($I$6:$I$481<>$I10))>0,"AMBIGUOUS — MAPS TO MULTIPLE TEAMS",IF(COUNTIF($H$6:$H$481,$H10)>1,"DUPLICATE x"&COUNTIF($H$6:$H$481,$H10)&" -> "&$I10,""))) | K10: Auburn
A11: UK | H11: Arkansas | J11: =IF($H11="","",IF(SUMPRODUCT(--(LOWER(TRIM($H$6:$H$481))=LOWER(TRIM($H11))),--($I$6:$I$481<>$I11))>0,"AMBIGUOUS — MAPS TO MULTIPLE TEAMS",IF(COUNTIF($H$6:$H$481,$H11)>1,"DUPLICATE x"&COUNTIF($H$6:$H$481,$H11)&" -> "&$I11,""))) | K11: AUB
A12: LSU | H12: Razorbacks | J12: =IF($H12="","",IF(SUMPRODUCT(--(LOWER(TRIM($H$6:$H$481))=LOWER(TRIM($H12))),--($I$6:$I$481<>$I12))>0,"AMBIGUOUS — MAPS TO MULTIPLE TEAMS",IF(COUNTIF($H$6:$H$481,$H12)>1,"DUPLICATE x"&COUNTIF($H$6:$H$481,$H12)&" -> "&$I12,""))) | K12: Florida
A13: MSST | H13: AUB | J13: =IF($H13="","",IF(SUMPRODUCT(--(LOWER(TRIM($H$6:$H$481))=LOWER(TRIM($H13))),--($I$6:$I$481<>$I13))>0,"AMBIGUOUS — MAPS TO MULTIPLE TEAMS",IF(COUNTIF($H$6:$H$481,$H13)>1,"DUPLICATE x"&COUNTIF($H$6:$H$481,$H13)&" -> "&$I13,""))) | K13: FLA
A14: MIZ | H14: Auburn | J14: =IF($H14="","",IF(SUMPRODUCT(--(LOWER(TRIM($H$6:$H$481))=LOWER(TRIM($H14))),--($I$6:$I$481<>$I14))>0,"AMBIGUOUS — MAPS TO MULTIPLE TEAMS",IF(COUNTIF($H$6:$H$481,$H14)>1,"DUPLICATE x"&COUNTIF($H$6:$H$481,$H14)&" -> "&$I14,""))) | K14: Georgia
A15: OU | H15: Tigers-AUB | J15: =IF($H15="","",IF(SUMPRODUCT(--(LOWER(TRIM($H$6:$H$481))=LOWER(TRIM($H15))),--($I$6:$I$481<>$I15))>0,"AMBIGUOUS — MAPS TO MULTIPLE TEAMS",IF(COUNTIF($H$6:$H$481,$H15)>1,"DUPLICATE x"&COUNTIF($H$6:$H$481,$H15)&" -> "&$I15,""))) | K15: UGA
A16: MISS | H16: FLA | J16: =IF($H16="","",IF(SUMPRODUCT(--(LOWER(TRIM($H$6:$H$481))=LOWER(TRIM($H16))),--($I$6:$I$481<>$I16))>0,"AMBIGUOUS — MAPS TO MULTIPLE TEAMS",IF(COUNTIF($H$6:$H$481,$H16)>1,"DUPLICATE x"&COUNTIF($H$6:$H$481,$H16)&" -> "&$I16,""))) | K16: Kentucky
A17: SCAR | H17: Florida | J17: =IF($H17="","",IF(SUMPRODUCT(--(LOWER(TRIM($H$6:$H$481))=LOWER(TRIM($H17))),--($I$6:$I$481<>$I17))>0,"AMBIGUOUS — MAPS TO MULTIPLE TEAMS",IF(COUNTIF($H$6:$H$481,$H17)>1,"DUPLICATE x"&COUNTIF($H$6:$H$481,$H17)&" -> "&$I17,""))) | K17: UK
... A143: CONN | H143: KAN | J143: =IF($H143="","",IF(SUMPRODUCT(--(LOWER(TRIM($H$6:$H$481))=LOWER(TRIM($H143))),--($I$6:$I$481<>$I143))>0,"AMBIGUOUS — MAPS TO MULTIPLE TEAMS",IF(COUNTIF($H$6:$H$481,$H143)>1,"DUPLICATE x"&COUNTIF($H$6:$H$481,$H143)&" -> "&$I143,""))) | K143: USU
H144: Kansas | J144: =IF($H144="","",IF(SUMPRODUCT(--(LOWER(TRIM($H$6:$H$481))=LOWER(TRIM($H144))),--($I$6:$I$481<>$I144))>0,"AMBIGUOUS — MAPS TO MULTIPLE TEAMS",IF(COUNTIF($H$6:$H$481,$H144)>1,"DUPLICATE x"&COUNTIF($H$6:$H$481,$H144)&" -> "&$I144,""))) | K144: Washington State
H145: KU | J145: =IF($H145="","",IF(SUMPRODUCT(--(LOWER(TRIM($H$6:$H$481))=LOWER(TRIM($H145))),--($I$6:$I$481<>$I145))>0,"AMBIGUOUS — MAPS TO MULTIPLE TEAMS",IF(COUNTIF($H$6:$H$481,$H145)>1,"DUPLICATE x"&COUNTIF($H$6:$H$481,$H145)&" -> "&$I145,""))) | K145: WSU
H146: Jayhawks | J146: =IF($H146="","",IF(SUMPRODUCT(--(LOWER(TRIM($H$6:$H$481))=LOWER(TRIM($H146))),--($I$6:$I$481<>$I146))>0,"AMBIGUOUS — MAPS TO MULTIPLE TEAMS",IF(COUNTIF($H$6:$H$481,$H146)>1,"DUPLICATE x"&COUNTIF($H$6:$H$481,$H146)&" -> "&$I146,""))) | K146: Army
H147: KSU | J147: =IF($H147="","",IF(SUMPRODUCT(--(LOWER(TRIM($H$6:$H$481))=LOWER(TRIM($H147))),--($I$6:$I$481<>$I147))>0,"AMBIGUOUS — MAPS TO MULTIPLE TEAMS",IF(COUNTIF($H$6:$H$481,$H147)>1,"DUPLICATE x"&COUNTIF($H$6:$H$481,$H147)&" -> "&$I147,""))) | K147: Charlotte
H148: Kansas State | J148: =IF($H148="","",IF(SUMPRODUCT(--(LOWER(TRIM($H$6:$H$481))=LOWER(TRIM($H148))),--($I$6:$I$481<>$I148))>0,"AMBIGUOUS — MAPS TO MULTIPLE TEAMS",IF(COUNTIF($H$6:$H$481,$H148)>1,"DUPLICATE x"&COUNTIF($H$6:$H$481,$H148)&" -> "&$I148,""))) | K148: CLT
H149: K-State | J149: =IF($H149="","",IF(SUMPRODUCT(--(LOWER(TRIM($H$6:$H$481))=LOWER(TRIM($H149))),--($I$6:$I$481<>$I149))>0,"AMBIGUOUS — MAPS TO MULTIPLE TEAMS",IF(COUNTIF($H$6:$H$481,$H149)>1,"DUPLICATE x"&COUNTIF($H$6:$H$481,$H149)&" -> "&$I149,""))) | K149: East Carolina
H150: OKST | J150: =IF($H150="","",IF(SUMPRODUCT(--(LOWER(TRIM($H$6:$H$481))=LOWER(TRIM($H150))),--($I$6:$I$481<>$I150))>0,"AMBIGUOUS — MAPS TO MULTIPLE TEAMS",IF(COUNTIF($H$6:$H$481,$H150)>1,"DUPLICATE x"&COUNTIF($H$6:$H$481,$H150)&" -> "&$I150,""))) | K150: ECU
H151: Oklahoma State | J151: =IF($H151="","",IF(SUMPRODUCT(--(LOWER(TRIM($H$6:$H$481))=LOWER(TRIM($H151))),--($I$6:$I$481<>$I151))>0,"AMBIGUOUS — MAPS TO MULTIPLE TEAMS",IF(COUNTIF($H$6:$H$481,$H151)>1,"DUPLICATE x"&COUNTIF($H$6:$H$481,$H151)&" -> "&$I151,""))) | K151: Florida Atlantic
H152: Ok State | J152: =IF($H152="","",IF(SUMPRODUCT(--(LOWER(TRIM($H$6:$H$481))=LOWER(TRIM($H152))),--($I$6:$I$481<>$I152))>0,"AMBIGUOUS — MAPS TO MULTIPLE TEAMS",IF(COUNTIF($H$6:$H$481,$H152)>1,"DUPLICATE x"&COUNTIF($H$6:$H$481,$H152)&" -> "&$I152,""))) | K152: FAU
H153: Pokes | J153: =IF($H153="","",IF(SUMPRODUCT(--(LOWER(TRIM($H$6:$H$481))=LOWER(TRIM($H153))),--($I$6:$I$481<>$I153))>0,"AMBIGUOUS — MAPS TO MULTIPLE TEAMS",IF(COUNTIF($H$6:$H$481,$H153)>1,"DUPLICATE x"&COUNTIF($H$6:$H$481,$H153)&" -> "&$I153,""))) | K153: Memphis
H154: TCU | J154: =IF($H154="","",IF(SUMPRODUCT(--(LOWER(TRIM($H$6:$H$481))=LOWER(TRIM($H154))),--($I$6:$I$481<>$I154))>0,"AMBIGUOUS — MAPS TO MULTIPLE TEAMS",IF(COUNTIF($H$6:$H$481,$H154)>1,"DUPLICATE x"&COUNTIF($H$6:$H$481,$H154)&" -> "&$I154,""))) | K154: MEM
H155: Horned Frogs | J155: =IF($H155="","",IF(SUMPRODUCT(--(LOWER(TRIM($H$6:$H$481))=LOWER(TRIM($H155))),--($I$6:$I$481<>$I155))>0,"AMBIGUOUS — MAPS TO MULTIPLE TEAMS",IF(COUNTIF($H$6:$H$481,$H155)>1,"DUPLICATE x"&COUNTIF($H$6:$H$481,$H155)&" -> "&$I155,""))) | K155: Navy
... H418: CCU | J418: =IF($H418="","",IF(SUMPRODUCT(--(LOWER(TRIM($H$6:$H$481))=LOWER(TRIM($H418))),--($I$6:$I$481<>$I418))>0,"AMBIGUOUS — MAPS TO MULTIPLE TEAMS",IF(COUNTIF($H$6:$H$481,$H418)>1,"DUPLICATE x"&COUNTIF($H$6:$H$481,$H418)&" -> "&$I418,""))) | K418: UConn Huskies
H419: Coastal Carolina | J419: =IF($H419="","",IF(SUMPRODUCT(--(LOWER(TRIM($H$6:$H$481))=LOWER(TRIM($H419))),--($I$6:$I$481<>$I419))>0,"AMBIGUOUS — MAPS TO MULTIPLE TEAMS",IF(COUNTIF($H$6:$H$481,$H419)>1,"DUPLICATE x"&COUNTIF($H$6:$H$481,$H419)&" -> "&$I419,"")))
H420: Coastal | J420: =IF($H420="","",IF(SUMPRODUCT(--(LOWER(TRIM($H$6:$H$481))=LOWER(TRIM($H420))),--($I$6:$I$481<>$I420))>0,"AMBIGUOUS — MAPS TO MULTIPLE TEAMS",IF(COUNTIF($H$6:$H$481,$H420)>1,"DUPLICATE x"&COUNTIF($H$6:$H$481,$H420)&" -> "&$I420,"")))
H421: Chanticleers | J421: =IF($H421="","",IF(SUMPRODUCT(--(LOWER(TRIM($H$6:$H$481))=LOWER(TRIM($H421))),--($I$6:$I$481<>$I421))>0,"AMBIGUOUS — MAPS TO MULTIPLE TEAMS",IF(COUNTIF($H$6:$H$481,$H421)>1,"DUPLICATE x"&COUNTIF($H$6:$H$481,$H421)&" -> "&$I421,"")))
H422: GASO | J422: =IF($H422="","",IF(SUMPRODUCT(--(LOWER(TRIM($H$6:$H$481))=LOWER(TRIM($H422))),--($I$6:$I$481<>$I422))>0,"AMBIGUOUS — MAPS TO MULTIPLE TEAMS",IF(COUNTIF($H$6:$H$481,$H422)>1,"DUPLICATE x"&COUNTIF($H$6:$H$481,$H422)&" -> "&$I422,"")))
H423: Georgia Southern | J423: =IF($H423="","",IF(SUMPRODUCT(--(LOWER(TRIM($H$6:$H$481))=LOWER(TRIM($H423))),--($I$6:$I$481<>$I423))>0,"AMBIGUOUS — MAPS TO MULTIPLE TEAMS",IF(COUNTIF($H$6:$H$481,$H423)>1,"DUPLICATE x"&COUNTIF($H$6:$H$481,$H423)&" -> "&$I423,"")))
H424: Ga Southern | J424: =IF($H424="","",IF(SUMPRODUCT(--(LOWER(TRIM($H$6:$H$481))=LOWER(TRIM($H424))),--($I$6:$I$481<>$I424))>0,"AMBIGUOUS — MAPS TO MULTIPLE TEAMS",IF(COUNTIF($H$6:$H$481,$H424)>1,"DUPLICATE x"&COUNTIF($H$6:$H$481,$H424)&" -> "&$I424,"")))
H425: Eagles-GASO | J425: =IF($H425="","",IF(SUMPRODUCT(--(LOWER(TRIM($H$6:$H$481))=LOWER(TRIM($H425))),--($I$6:$I$481<>$I425))>0,"AMBIGUOUS — MAPS TO MULTIPLE TEAMS",IF(COUNTIF($H$6:$H$481,$H425)>1,"DUPLICATE x"&COUNTIF($H$6:$H$481,$H425)&" -> "&$I425,"")))
H426: GAST | J426: =IF($H426="","",IF(SUMPRODUCT(--(LOWER(TRIM($H$6:$H$481))=LOWER(TRIM($H426))),--($I$6:$I$481<>$I426))>0,"AMBIGUOUS — MAPS TO MULTIPLE TEAMS",IF(COUNTIF($H$6:$H$481,$H426)>1,"DUPLICATE x"&COUNTIF($H$6:$H$481,$H426)&" -> "&$I426,"")))
H427: Georgia State | J427: =IF($H427="","",IF(SUMPRODUCT(--(LOWER(TRIM($H$6:$H$481))=LOWER(TRIM($H427))),--($I$6:$I$481<>$I427))>0,"AMBIGUOUS — MAPS TO MULTIPLE TEAMS",IF(COUNTIF($H$6:$H$481,$H427)>1,"DUPLICATE x"&COUNTIF($H$6:$H$481,$H427)&" -> "&$I427,"")))
H428: Ga State | J428: =IF($H428="","",IF(SUMPRODUCT(--(LOWER(TRIM($H$6:$H$481))=LOWER(TRIM($H428))),--($I$6:$I$481<>$I428))>0,"AMBIGUOUS — MAPS TO MULTIPLE TEAMS",IF(COUNTIF($H$6:$H$481,$H428)>1,"DUPLICATE x"&COUNTIF($H$6:$H$481,$H428)&" -> "&$I428,"")))
H429: Panthers-GAST | J429: =IF($H429="","",IF(SUMPRODUCT(--(LOWER(TRIM($H$6:$H$481))=LOWER(TRIM($H429))),--($I$6:$I$481<>$I429))>0,"AMBIGUOUS — MAPS TO MULTIPLE TEAMS",IF(COUNTIF($H$6:$H$481,$H429)>1,"DUPLICATE x"&COUNTIF($H$6:$H$481,$H429)&" -> "&$I429,"")))
...

Sheet PRESEASON
Z5: FINAL PRIOR (pts vs avg)
Z6: =IF($A6="","",IF($Y6=0,"",(SETTINGS!$B$28*IF(ISNUMBER($G6),$G6,0)+SETTINGS!$B$29*IF(ISNUMBER($K6),$K6,0)+SETTINGS!$B$30*IF(ISNUMBER($P6),$P6,0)+SETTINGS!$B$31*IF(ISNUMBER($T6),$T6,0)+SETTINGS!$B$32*IF(ISNUMBER($X6),$X6,0))/$Y6))
Z7: =IF($A7="","",IF($Y7=0,"",(SETTINGS!$B$28*IF(ISNUMBER($G7),$G7,0)+SETTINGS!$B$29*IF(ISNUMBER($K7),$K7,0)+SETTINGS!$B$30*IF(ISNUMBER($P7),$P7,0)+SETTINGS!$B$31*IF(ISNUMBER($T7),$T7,0)+SETTINGS!$B$32*IF(ISNUMBER($X7),$X7,0))/$Y7))
Z8: =IF($A8="","",IF($Y8=0,"",(SETTINGS!$B$28*IF(ISNUMBER($G8),$G8,0)+SETTINGS!$B$29*IF(ISNUMBER($K8),$K8,0)+SETTINGS!$B$30*IF(ISNUMBER($P8),$P8,0)+SETTINGS!$B$31*IF(ISNUMBER($T8),$T8,0)+SETTINGS!$B$32*IF(ISNUMBER($X8),$X8,0))/$Y8))
Z9: =IF($A9="","",IF($Y9=0,"",(SETTINGS!$B$28*IF(ISNUMBER($G9),$G9,0)+SETTINGS!$B$29*IF(ISNUMBER($K9),$K9,0)+SETTINGS!$B$30*IF(ISNUMBER($P9),$P9,0)+SETTINGS!$B$31*IF(ISNUMBER($T9),$T9,0)+SETTINGS!$B$32*IF(ISNUMBER($X9),$X9,0))/$Y9))
Z10: =IF($A10="","",IF($Y10=0,"",(SETTINGS!$B$28*IF(ISNUMBER($G10),$G10,0)+SETTINGS!$B$29*IF(ISNUMBER($K10),$K10,0)+SETTINGS!$B$30*IF(ISNUMBER($P10),$P10,0)+SETTINGS!$B$31*IF(ISNUMBER($T10),$T10,0)+SETTINGS!$B$32*IF(ISNUMBER($X10),$X10,0))/$Y10))
Z11: =IF($A11="","",IF($Y11=0,"",(SETTINGS!$B$28*IF(ISNUMBER($G11),$G11,0)+SETTINGS!$B$29*IF(ISNUMBER($K11),$K11,0)+SETTINGS!$B$30*IF(ISNUMBER($P11),$P11,0)+SETTINGS!$B$31*IF(ISNUMBER($T11),$T11,0)+SETTINGS!$B$32*IF(ISNUMBER($X11),$X11,0))/$Y11))
Z12: =IF($A12="","",IF($Y12=0,"",(SETTINGS!$B$28*IF(ISNUMBER($G12),$G12,0)+SETTINGS!$B$29*IF(ISNUMBER($K12),$K12,0)+SETTINGS!$B$30*IF(ISNUMBER($P12),$P12,0)+SETTINGS!$B$31*IF(ISNUMBER($T12),$T12,0)+SETTINGS!$B$32*IF(ISNUMBER($X12),$X12,0))/$Y12))
Z13: =IF($A13="","",IF($Y13=0,"",(SETTINGS!$B$28*IF(ISNUMBER($G13),$G13,0)+SETTINGS!$B$29*IF(ISNUMBER($K13),$K13,0)+SETTINGS!$B$30*IF(ISNUMBER($P13),$P13,0)+SETTINGS!$B$31*IF(ISNUMBER($T13),$T13,0)+SETTINGS!$B$32*IF(ISNUMBER($X13),$X13,0))/$Y13))
Z14: =IF($A14="","",IF($Y14=0,"",(SETTINGS!$B$28*IF(ISNUMBER($G14),$G14,0)+SETTINGS!$B$29*IF(ISNUMBER($K14),$K14,0)+SETTINGS!$B$30*IF(ISNUMBER($P14),$P14,0)+SETTINGS!$B$31*IF(ISNUMBER($T14),$T14,0)+SETTINGS!$B$32*IF(ISNUMBER($X14),$X14,0))/$Y14))
Z15: =IF($A15="","",IF($Y15=0,"",(SETTINGS!$B$28*IF(ISNUMBER($G15),$G15,0)+SETTINGS!$B$29*IF(ISNUMBER($K15),$K15,0)+SETTINGS!$B$30*IF(ISNUMBER($P15),$P15,0)+SETTINGS!$B$31*IF(ISNUMBER($T15),$T15,0)+SETTINGS!$B$32*IF(ISNUMBER($X15),$X15,0))/$Y15))
Z16: =IF($A16="","",IF($Y16=0,"",(SETTINGS!$B$28*IF(ISNUMBER($G16),$G16,0)+SETTINGS!$B$29*IF(ISNUMBER($K16),$K16,0)+SETTINGS!$B$30*IF(ISNUMBER($P16),$P16,0)+SETTINGS!$B$31*IF(ISNUMBER($T16),$T16,0)+SETTINGS!$B$32*IF(ISNUMBER($X16),$X16,0))/$Y16))
Z17: =IF($A17="","",IF($Y17=0,"",(SETTINGS!$B$28*IF(ISNUMBER($G17),$G17,0)+SETTINGS!$B$29*IF(ISNUMBER($K17),$K17,0)+SETTINGS!$B$30*IF(ISNUMBER($P17),$P17,0)+SETTINGS!$B$31*IF(ISNUMBER($T17),$T17,0)+SETTINGS!$B$32*IF(ISNUMBER($X17),$X17,0))/$Y17))
... Z143: =IF($A143="","",IF($Y143=0,"",(SETTINGS!$B$28*IF(ISNUMBER($G143),$G143,0)+SETTINGS!$B$29*IF(ISNUMBER($K143),$K143,0)+SETTINGS!$B$30*IF(ISNUMBER($P143),$P143,0)+SETTINGS!$B$31*IF(ISNUMBER($T143),$T143,0)+SETTINGS!$B$32*IF(ISNUMBER($X143),$X143,0))/$Y143))

Sheet SETTINGS
B3: 2026
B6: 2.5
B7: 0
B8: 1
B9: 1.5
B10: 3
B11: N
B12: 2.5

Sheet MARKET LINES
A1: MARKET LINES — from your OddsLogic / Circa screenshots ONLY
A2: SIGN CONVENTION: enter Favorite (canonical abbrev, e.g. UGA) + POSITIVE spread. Georgia -7.5 -> Favorite=UGA, Spread=7.5. Never enter -7.5. Bare 'Miami' rejects — use MIA or M-OH. FCS favorites: type the name exactly as shown in the matchup. No line is ever guessed from a public website.
A5: GameID

Sheet AUDIT
B6: =IF(COUNTIF('TEAM MAP'!$A$6:$A$143,"?*")=138,"OK","FAIL")
B7: {=IF(SUMPRODUCT(--(COUNTIF('TEAM MAP'!$A$6:$A$143,'TEAM MAP'!$A$6:$A$143)>1))=0,"OK","FAIL")}
B8: {=IF(SUMPRODUCT(--('TEAM MAP'!$H$6:$H$481<>""),--(COUNTIF('TEAM MAP'!$H$6:$H$481,'TEAM MAP'!$H$6:$H$481)>1))=0,"OK","FAIL")}
B9: =IF(COUNT(PRESEASON!$Z$6:$Z$143)=0,"N/A — no ratings loaded (Phase 4)",TEXT(AVERAGE(PRESEASON!$Z$6:$Z$143),"0.00"))
B12: =IF(SETTINGS!$B$11="N","OK (OFF)","CHECK — toggle is "&SETTINGS!$B$11)
B13: =IF(AND(SETTINGS!$B$8=1,SETTINGS!$B$9=1.5,SETTINGS!$B$10=3),"OK","CHANGED — log in CHANGELOG")
B14: =IF(AND(SETTINGS!$B$6=2.5,SETTINGS!$B$7=0),"OK","CHANGED — log in CHANGELOG")
B15: =IF(SETTINGS!$B$12=2.5,"OK","CHANGED — log in CHANGELOG")
B16: =IF(COUNTIF('MARKET LINES'!$A$6:$A$1005,"?*")+COUNT('MARKET LINES'!$A$6:$A$1005)=0,"OK — clean","REMOVE TEST LINES")
B17: =IF(COUNTIF('TEAM MAP'!$J$6:$J$481,"AMBIGUOUS — MAPS TO MULTIPLE TEAMS")=0,"OK","FAIL — move alias to blocked list")
B18: {=IF(SUMPRODUCT(--('TEAM MAP'!$K$6:$K$481<>""),--(COUNTIF('TEAM MAP'!$K$6:$K$481,'TEAM MAP'!$K$6:$K$481)>1))=0,"OK","FAIL")}
