Workbook

Sheet TEAM MAP
A6: ALA | B6: Alabama | C6: SEC | D6: FBS | E6: N | K6: Alabama | L6: ALA | N6: SEC
A7: ARK | B7: Arkansas | C7: SEC | D7: FBS | E7: N | K7: ALA | L7: ALA | N7: Big Ten
A8: AUB | B8: Auburn | C8: SEC | D8: FBS | E8: N | K8: Arkansas | L8: ARK | N8: Big 12
A9: FLA | B9: Florida | C9: SEC | D9: FBS | E9: N | K9: ARK | L9: ARK | N9: ACC
A10: UGA | B10: Georgia | C10: SEC | D10: FBS | E10: N | K10: Auburn | L10: AUB | N10: Pac-12
A11: UK | B11: Kentucky | C11: SEC | D11: FBS | E11: N | F11: Do not confuse UK with KENT (Kent State) | K11: AUB | L11: AUB | N11: American Athletic
A12: LSU | B12: LSU | C12: SEC | D12: FBS | E12: N | K12: Florida | L12: FLA | N12: American
A13: MSST | B13: Mississippi State | C13: SEC | D13: FBS | E13: N | F13: MSU is AMBIGUOUS - blocked alias | K13: FLA | L13: FLA | N13: Conference USA
A14: MIZ | B14: Missouri | C14: SEC | D14: FBS | E14: N | K14: Georgia | L14: UGA | N14: Mid-American
A15: OU | B15: Oklahoma | C15: SEC | D15: FBS | E15: N | K15: UGA | L15: UGA | N15: MAC
A16: MISS | B16: Ole Miss | C16: SEC | D16: FBS | E16: N | F16: CFBD name: Ole Miss | K16: Kentucky | L16: UK | N16: Mountain West
A17: SCAR | B17: South Carolina | C17: SEC | D17: FBS | E17: N | F17: SC is AMBIGUOUS - blocked alias | K17: UK | L17: UK | N17: Sun Belt
A18: TENN | B18: Tennessee | C18: SEC | D18: FBS | E18: N | F18: UT is AMBIGUOUS - blocked alias | K18: LSU | L18: LSU | N18: FBS Independents
A19: TEX | B19: Texas | C19: SEC | D19: FBS | E19: N | F19: UT is AMBIGUOUS - blocked alias | K19: Mississippi State | L19: MSST | N19: Independent
A20: TAMU | B20: Texas A&M | C20: SEC | D20: FBS | E20: N | K20: MSST | L20: MSST | N20: Atlantic Coast Conference
A21: VAN | B21: Vanderbilt | C21: SEC | D21: FBS | E21: N | K21: Missouri | L21: MIZ | N21: Big Ten Conference
A22: ILL | B22: Illinois | C22: Big Ten | D22: FBS | E22: N | K22: MIZ | L22: MIZ | N22: Big 12 Conference
A23: IND | B23: Indiana | C23: Big Ten | D23: FBS | E23: N | K23: Oklahoma | L23: OU | N23: Southeastern Conference
A24: IOWA | B24: Iowa | C24: Big Ten | D24: FBS | E24: N | K24: OU | L24: OU | N24: Pac-12 Conference
A25: MD | B25: Maryland | C25: Big Ten | D25: FBS | E25: N | K25: Ole Miss | L25: MISS | N25: American Conference
A26: MICH | B26: Michigan | C26: Big Ten | D26: FBS | E26: N | F26: UM is AMBIGUOUS - blocked alias | K26: MISS | L26: MISS | N26: Mid-American Conference
A27: MSU | B27: Michigan State | C27: Big Ten | D27: FBS | E27: N | F27: MSU reserved here; MSST/MOST elsewhere | K27: South Carolina | L27: SCAR | N27: Mountain West Conference
A28: MINN | B28: Minnesota | C28: Big Ten | D28: FBS | E28: N | K28: SCAR | L28: SCAR | N28: Sun Belt Conference
A29: NEB | B29: Nebraska | C29: Big Ten | D29: FBS | E29: N | K29: Tennessee | L29: TENN
A30: NW | B30: Northwestern | C30: Big Ten | D30: FBS | E30: N | F30: NU not used (ambiguous) | K30: TENN | L30: TENN
A31: OHST | B31: Ohio State | C31: Big Ten | D31: FBS | E31: N | F31: OSU is AMBIGUOUS - blocked alias | K31: Texas | L31: TEX
A32: ORE | B32: Oregon | C32: Big Ten | D32: FBS | E32: N | K32: TEX | L32: TEX
A33: PSU | B33: Penn State | C33: Big Ten | D33: FBS | E33: N | K33: Texas A&M | L33: TAMU
A34: PUR | B34: Purdue | C34: Big Ten | D34: FBS | E34: N | K34: TAMU | L34: TAMU
A35: RUTG | B35: Rutgers | C35: Big Ten | D35: FBS | E35: N | K35: Vanderbilt | L35: VAN
A36: UCLA | B36: UCLA | C36: Big Ten | D36: FBS | E36: N | K36: VAN | L36: VAN
A37: USC | B37: USC | C37: Big Ten | D37: FBS | E37: N | K37: Illinois | L37: ILL
A38: WASH | B38: Washington | C38: Big Ten | D38: FBS | E38: N | K38: ILL | L38: ILL
A39: WISC | B39: Wisconsin | C39: Big Ten | D39: FBS | E39: N | K39: Indiana | L39: IND
A40: ARIZ | B40: Arizona | C40: Big 12 | D40: FBS | E40: N | K40: IND | L40: IND
A41: AZST | B41: Arizona State | C41: Big 12 | D41: FBS | E41: N | F41: ASU maps here (Ark State = ARST) | K41: Iowa | L41: IOWA
A42: BAY | B42: Baylor | C42: Big 12 | D42: FBS | E42: N | K42: Maryland | L42: MD
A43: BYU | B43: BYU | C43: Big 12 | D43: FBS | E43: N | K43: MD | L43: MD
A44: CIN | B44: Cincinnati | C44: Big 12 | D44: FBS | E44: N | K44: Michigan | L44: MICH
A45: COLO | B45: Colorado | C45: Big 12 | D45: FBS | E45: N | K45: MICH | L45: MICH
...

Sheet PRESEASON
A6: =IF('TEAM MAP'!$A6="","",'TEAM MAP'!$A6) | B6: =IF('TEAM MAP'!$A6="","",'TEAM MAP'!$B6) | C6: =IF('TEAM MAP'!$A6="","",'TEAM MAP'!$D6) | D6: 18.2 | E6: 46108 | F6: https://www.espn.com/college-football/story/_/id/48306284/2026-college-football-sp+-rankings-138-fbs-teams | G6: =IF($D6="","",$D6-AVERAGE($D$6:$D$143)) | H6: 20.1 | I6: 46222 | J6: https://www.espn.com/college-football/fpi | K6: =IF($H6="","",$H6-AVERAGE($H$6:$H$143)) | M6: =IF($L6="","",IF($C6="FBS-RECLASSIFYING",IF($L6<0,$L6,$L6*(1-SETTINGS!$B$16)),$L6*(1-SETTINGS!$B$15))) | P6: =IF($M6="","",$M6-AVERAGE($M$6:$M$143)) | Q6: 21.6 | R6: 46222 | S6: https://www.teamrankings.com/college-football/ranking/predictive-by-other | T6: =IF($Q6="","",$Q6-AVERAGE($Q$6:$Q$143)) | X6: =IF($U6="","",$U6-AVERAGE($U$6:$U$143)) | Y6: =IF($A6="","",SETTINGS!$B$28*ISNUMBER($G6)+SETTINGS!$B$29*ISNUMBER($K6)+SETTINGS!$B$30*ISNUMBER($P6)+SETTINGS!$B$31*ISNUMBER($T6)+SETTINGS!$B$32*ISNUMBER($X6)) | Z6: =IF($A6="","",IF($Y6=0,"",(SETTINGS!$B$28*IF(ISNUMBER($G6),$G6,0)+SETTINGS!$B$29*IF(ISNUMBER($K6),$K6,0)+SETTINGS!$B$30*IF(ISNUMBER($P6),$P6,0)+SETTINGS!$B$31*IF(ISNUMBER($T6),$T6,0)+SETTINGS!$B$32*IF(ISNUMBER($X6),$X6,0))/$Y6)) | AA6: =IF($A6="","",COUNT($D6,$H6,$L6,$Q6,$U6)) | AB6: =IF($A6="","",IF($AA6<=1,"SINGLE-SOURCE / LOW CONFIDENCE","")) | AC6: =IF($A6="","",IF(AND($C6="FBS-RECLASSIFYING",ISNUMBER($L6),$L6<0),"NO-AUTO-UPGRADE GUARD APPLIED",""))
A7: =IF('TEAM MAP'!$A7="","",'TEAM MAP'!$A7) | B7: =IF('TEAM MAP'!$A7="","",'TEAM MAP'!$B7) | C7: =IF('TEAM MAP'!$A7="","",'TEAM MAP'!$D7) | D7: 5 | E7: 46108 | F7: https://www.espn.com/college-football/story/_/id/48306284/2026-college-football-sp+-rankings-138-fbs-teams | G7: =IF($D7="","",$D7-AVERAGE($D$6:$D$143)) | H7: 4.4 | I7: 46222 | J7: https://www.espn.com/college-football/fpi | K7: =IF($H7="","",$H7-AVERAGE($H$6:$H$143)) | M7: =IF($L7="","",IF($C7="FBS-RECLASSIFYING",IF($L7<0,$L7,$L7*(1-SETTINGS!$B$16)),$L7*(1-SETTINGS!$B$15))) | P7: =IF($M7="","",$M7-AVERAGE($M$6:$M$143)) | Q7: 4.7 | R7: 46222 | S7: https://www.teamrankings.com/college-football/ranking/predictive-by-other | T7: =IF($Q7="","",$Q7-AVERAGE($Q$6:$Q$143)) | X7: =IF($U7="","",$U7-AVERAGE($U$6:$U$143)) | Y7: =IF($A7="","",SETTINGS!$B$28*ISNUMBER($G7)+SETTINGS!$B$29*ISNUMBER($K7)+SETTINGS!$B$30*ISNUMBER($P7)+SETTINGS!$B$31*ISNUMBER($T7)+SETTINGS!$B$32*ISNUMBER($X7)) | Z7: =IF($A7="","",IF($Y7=0,"",(SETTINGS!$B$28*IF(ISNUMBER($G7),$G7,0)+SETTINGS!$B$29*IF(ISNUMBER($K7),$K7,0)+SETTINGS!$B$30*IF(ISNUMBER($P7),$P7,0)+SETTINGS!$B$31*IF(ISNUMBER($T7),$T7,0)+SETTINGS!$B$32*IF(ISNUMBER($X7),$X7,0))/$Y7)) | AA7: =IF($A7="","",COUNT($D7,$H7,$L7,$Q7,$U7)) | AB7: =IF($A7="","",IF($AA7<=1,"SINGLE-SOURCE / LOW CONFIDENCE","")) | AC7: =IF($A7="","",IF(AND($C7="FBS-RECLASSIFYING",ISNUMBER($L7),$L7<0),"NO-AUTO-UPGRADE GUARD APPLIED",""))
A8: =IF('TEAM MAP'!$A8="","",'TEAM MAP'!$A8) | B8: =IF('TEAM MAP'!$A8="","",'TEAM MAP'!$B8) | C8: =IF('TEAM MAP'!$A8="","",'TEAM MAP'!$D8) | D8: 11.2 | E8: 46108 | F8: https://www.espn.com/college-football/story/_/id/48306284/2026-college-football-sp+-rankings-138-fbs-teams | G8: =IF($D8="","",$D8-AVERAGE($D$6:$D$143)) | H8: 12 | I8: 46222 | J8: https://www.espn.com/college-football/fpi | K8: =IF($H8="","",$H8-AVERAGE($H$6:$H$143)) | M8: =IF($L8="","",IF($C8="FBS-RECLASSIFYING",IF($L8<0,$L8,$L8*(1-SETTINGS!$B$16)),$L8*(1-SETTINGS!$B$15))) | P8: =IF($M8="","",$M8-AVERAGE($M$6:$M$143)) | Q8: 13.4 | R8: 46222 | S8: https://www.teamrankings.com/college-football/ranking/predictive-by-other | T8: =IF($Q8="","",$Q8-AVERAGE($Q$6:$Q$143)) | X8: =IF($U8="","",$U8-AVERAGE($U$6:$U$143)) | Y8: =IF($A8="","",SETTINGS!$B$28*ISNUMBER($G8)+SETTINGS!$B$29*ISNUMBER($K8)+SETTINGS!$B$30*ISNUMBER($P8)+SETTINGS!$B$31*ISNUMBER($T8)+SETTINGS!$B$32*ISNUMBER($X8)) | Z8: =IF($A8="","",IF($Y8=0,"",(SETTINGS!$B$28*IF(ISNUMBER($G8),$G8,0)+SETTINGS!$B$29*IF(ISNUMBER($K8),$K8,0)+SETTINGS!$B$30*IF(ISNUMBER($P8),$P8,0)+SETTINGS!$B$31*IF(ISNUMBER($T8),$T8,0)+SETTINGS!$B$32*IF(ISNUMBER($X8),$X8,0))/$Y8)) | AA8: =IF($A8="","",COUNT($D8,$H8,$L8,$Q8,$U8)) | AB8: =IF($A8="","",IF($AA8<=1,"SINGLE-SOURCE / LOW CONFIDENCE","")) | AC8: =IF($A8="","",IF(AND($C8="FBS-RECLASSIFYING",ISNUMBER($L8),$L8<0),"NO-AUTO-UPGRADE GUARD APPLIED",""))
A9: =IF('TEAM MAP'!$A9="","",'TEAM MAP'!$A9) | B9: =IF('TEAM MAP'!$A9="","",'TEAM MAP'!$B9) | C9: =IF('TEAM MAP'!$A9="","",'TEAM MAP'!$D9) | D9: 14.9 | E9: 46108 | F9: https://www.espn.com/college-football/story/_/id/48306284/2026-college-football-sp+-rankings-138-fbs-teams | G9: =IF($D9="","",$D9-AVERAGE($D$6:$D$143)) | H9: 13.6 | I9: 46222 | J9: https://www.espn.com/college-football/fpi | K9: =IF($H9="","",$H9-AVERAGE($H$6:$H$143)) | M9: =IF($L9="","",IF($C9="FBS-RECLASSIFYING",IF($L9<0,$L9,$L9*(1-SETTINGS!$B$16)),$L9*(1-SETTINGS!$B$15))) | P9: =IF($M9="","",$M9-AVERAGE($M$6:$M$143)) | Q9: 17.4 | R9: 46222 | S9: https://www.teamrankings.com/college-football/ranking/predictive-by-other | T9: =IF($Q9="","",$Q9-AVERAGE($Q$6:$Q$143)) | X9: =IF($U9="","",$U9-AVERAGE($U$6:$U$143)) | Y9: =IF($A9="","",SETTINGS!$B$28*ISNUMBER($G9)+SETTINGS!$B$29*ISNUMBER($K9)+SETTINGS!$B$30*ISNUMBER($P9)+SETTINGS!$B$31*ISNUMBER($T9)+SETTINGS!$B$32*ISNUMBER($X9)) | Z9: =IF($A9="","",IF($Y9=0,"",(SETTINGS!$B$28*IF(ISNUMBER($G9),$G9,0)+SETTINGS!$B$29*IF(ISNUMBER($K9),$K9,0)+SETTINGS!$B$30*IF(ISNUMBER($P9),$P9,0)+SETTINGS!$B$31*IF(ISNUMBER($T9),$T9,0)+SETTINGS!$B$32*IF(ISNUMBER($X9),$X9,0))/$Y9)) | AA9: =IF($A9="","",COUNT($D9,$H9,$L9,$Q9,$U9)) | AB9: =IF($A9="","",IF($AA9<=1,"SINGLE-SOURCE / LOW CONFIDENCE","")) | AC9: =IF($A9="","",IF(AND($C9="FBS-RECLASSIFYING",ISNUMBER($L9),$L9<0),"NO-AUTO-UPGRADE GUARD APPLIED",""))
A10: =IF('TEAM MAP'!$A10="","",'TEAM MAP'!$A10) | B10: =IF('TEAM MAP'!$A10="","",'TEAM MAP'!$B10) | C10: =IF('TEAM MAP'!$A10="","",'TEAM MAP'!$D10) | D10: 25.5 | E10: 46108 | F10: https://www.espn.com/college-football/story/_/id/48306284/2026-college-football-sp+-rankings-138-fbs-teams | G10: =IF($D10="","",$D10-AVERAGE($D$6:$D$143)) | H10: 24.8 | I10: 46222 | J10: https://www.espn.com/college-football/fpi | K10: =IF($H10="","",$H10-AVERAGE($H$6:$H$143)) | M10: =IF($L10="","",IF($C10="FBS-RECLASSIFYING",IF($L10<0,$L10,$L10*(1-SETTINGS!$B$16)),$L10*(1-SETTINGS!$B$15))) | P10: =IF($M10="","",$M10-AVERAGE($M$6:$M$143)) | Q10: 28.4 | R10: 46222 | S10: https://www.teamrankings.com/college-football/ranking/predictive-by-other | T10: =IF($Q10="","",$Q10-AVERAGE($Q$6:$Q$143)) | X10: =IF($U10="","",$U10-AVERAGE($U$6:$U$143)) | Y10: =IF($A10="","",SETTINGS!$B$28*ISNUMBER($G10)+SETTINGS!$B$29*ISNUMBER($K10)+SETTINGS!$B$30*ISNUMBER($P10)+SETTINGS!$B$31*ISNUMBER($T10)+SETTINGS!$B$32*ISNUMBER($X10)) | Z10: =IF($A10="","",IF($Y10=0,"",(SETTINGS!$B$28*IF(ISNUMBER($G10),$G10,0)+SETTINGS!$B$29*IF(ISNUMBER($K10),$K10,0)+SETTINGS!$B$30*IF(ISNUMBER($P10),$P10,0)+SETTINGS!$B$31*IF(ISNUMBER($T10),$T10,0)+SETTINGS!$B$32*IF(ISNUMBER($X10),$X10,0))/$Y10)) | AA10: =IF($A10="","",COUNT($D10,$H10,$L10,$Q10,$U10)) | AB10: =IF($A10="","",IF($AA10<=1,"SINGLE-SOURCE / LOW CONFIDENCE","")) | AC10: =IF($A10="","",IF(AND($C10="FBS-RECLASSIFYING",ISNUMBER($L10),$L10<0),"NO-AUTO-UPGRADE GUARD APPLIED",""))
A11: =IF('TEAM MAP'!$A11="","",'TEAM MAP'!$A11) | B11: =IF('TEAM MAP'!$A11="","",'TEAM MAP'!$B11) | C11: =IF('TEAM MAP'!$A11="","",'TEAM MAP'!$D11) | D11: 3.8 | E11: 46108 | F11: https://www.espn.com/college-football/story/_/id/48306284/2026-college-football-sp+-rankings-138-fbs-teams | G11: =IF($D11="","",$D11-AVERAGE($D$6:$D$143)) | H11: 5.4 | I11: 46222 | J11: https://www.espn.com/college-football/fpi | K11: =IF($H11="","",$H11-AVERAGE($H$6:$H$143)) | M11: =IF($L11="","",IF($C11="FBS-RECLASSIFYING",IF($L11<0,$L11,$L11*(1-SETTINGS!$B$16)),$L11*(1-SETTINGS!$B$15))) | P11: =IF($M11="","",$M11-AVERAGE($M$6:$M$143)) | Q11: 8.9 | R11: 46222 | S11: https://www.teamrankings.com/college-football/ranking/predictive-by-other | T11: =IF($Q11="","",$Q11-AVERAGE($Q$6:$Q$143)) | X11: =IF($U11="","",$U11-AVERAGE($U$6:$U$143)) | Y11: =IF($A11="","",SETTINGS!$B$28*ISNUMBER($G11)+SETTINGS!$B$29*ISNUMBER($K11)+SETTINGS!$B$30*ISNUMBER($P11)+SETTINGS!$B$31*ISNUMBER($T11)+SETTINGS!$B$32*ISNUMBER($X11)) | Z11: =IF($A11="","",IF($Y11=0,"",(SETTINGS!$B$28*IF(ISNUMBER($G11),$G11,0)+SETTINGS!$B$29*IF(ISNUMBER($K11),$K11,0)+SETTINGS!$B$30*IF(ISNUMBER($P11),$P11,0)+SETTINGS!$B$31*IF(ISNUMBER($T11),$T11,0)+SETTINGS!$B$32*IF(ISNUMBER($X11),$X11,0))/$Y11)) | AA11: =IF($A11="","",COUNT($D11,$H11,$L11,$Q11,$U11)) | AB11: =IF($A11="","",IF($AA11<=1,"SINGLE-SOURCE / LOW CONFIDENCE","")) | AC11: =IF($A11="","",IF(AND($C11="FBS-RECLASSIFYING",ISNUMBER($L11),$L11<0),"NO-AUTO-UPGRADE GUARD APPLIED",""))
A12: =IF('TEAM MAP'!$A12="","",'TEAM MAP'!$A12) | B12: =IF('TEAM MAP'!$A12="","",'TEAM MAP'!$B12) | C12: =IF('TEAM MAP'!$A12="","",'TEAM MAP'!$D12) | D12: 20.2 | E12: 46108 | F12: https://www.espn.com/college-football/story/_/id/48306284/2026-college-football-sp+-rankings-138-fbs-teams | G12: =IF($D12="","",$D12-AVERAGE($D$6:$D$143)) | H12: 20 | I12: 46222 | J12: https://www.espn.com/college-football/fpi | K12: =IF($H12="","",$H12-AVERAGE($H$6:$H$143)) | M12: =IF($L12="","",IF($C12="FBS-RECLASSIFYING",IF($L12<0,$L12,$L12*(1-SETTINGS!$B$16)),$L12*(1-SETTINGS!$B$15))) | P12: =IF($M12="","",$M12-AVERAGE($M$6:$M$143)) | Q12: 22.1 | R12: 46222 | S12: https://www.teamrankings.com/college-football/ranking/predictive-by-other | T12: =IF($Q12="","",$Q12-AVERAGE($Q$6:$Q$143)) | X12: =IF($U12="","",$U12-AVERAGE($U$6:$U$143)) | Y12: =IF($A12="","",SETTINGS!$B$28*ISNUMBER($G12)+SETTINGS!$B$29*ISNUMBER($K12)+SETTINGS!$B$30*ISNUMBER($P12)+SETTINGS!$B$31*ISNUMBER($T12)+SETTINGS!$B$32*ISNUMBER($X12)) | Z12: =IF($A12="","",IF($Y12=0,"",(SETTINGS!$B$28*IF(ISNUMBER($G12),$G12,0)+SETTINGS!$B$29*IF(ISNUMBER($K12),$K12,0)+SETTINGS!$B$30*IF(ISNUMBER($P12),$P12,0)+SETTINGS!$B$31*IF(ISNUMBER($T12),$T12,0)+SETTINGS!$B$32*IF(ISNUMBER($X12),$X12,0))/$Y12)) | AA12: =IF($A12="","",COUNT($D12,$H12,$L12,$Q12,$U12)) | AB12: =IF($A12="","",IF($AA12<=1,"SINGLE-SOURCE / LOW CONFIDENCE","")) | AC12: =IF($A12="","",IF(AND($C12="FBS-RECLASSIFYING",ISNUMBER($L12),$L12<0),"NO-AUTO-UPGRADE GUARD APPLIED",""))
A13: =IF('TEAM MAP'!$A13="","",'TEAM MAP'!$A13) | B13: =IF('TEAM MAP'!$A13="","",'TEAM MAP'!$B13) | C13: =IF('TEAM MAP'!$A13="","",'TEAM MAP'!$D13) | D13: 3.9 | E13: 46108 | F13: https://www.espn.com/college-football/story/_/id/48306284/2026-college-football-sp+-rankings-138-fbs-teams | G13: =IF($D13="","",$D13-AVERAGE($D$6:$D$143)) | H13: 4.1 | I13: 46222 | J13: https://www.espn.com/college-football/fpi | K13: =IF($H13="","",$H13-AVERAGE($H$6:$H$143)) | M13: =IF($L13="","",IF($C13="FBS-RECLASSIFYING",IF($L13<0,$L13,$L13*(1-SETTINGS!$B$16)),$L13*(1-SETTINGS!$B$15))) | P13: =IF($M13="","",$M13-AVERAGE($M$6:$M$143)) | Q13: 6.4 | R13: 46222 | S13: https://www.teamrankings.com/college-football/ranking/predictive-by-other | T13: =IF($Q13="","",$Q13-AVERAGE($Q$6:$Q$143)) | X13: =IF($U13="","",$U13-AVERAGE($U$6:$U$143)) | Y13: =IF($A13="","",SETTINGS!$B$28*ISNUMBER($G13)+SETTINGS!$B$29*ISNUMBER($K13)+SETTINGS!$B$30*ISNUMBER($P13)+SETTINGS!$B$31*ISNUMBER($T13)+SETTINGS!$B$32*ISNUMBER($X13)) | Z13: =IF($A13="","",IF($Y13=0,"",(SETTINGS!$B$28*IF(ISNUMBER($G13),$G13,0)+SETTINGS!$B$29*IF(ISNUMBER($K13),$K13,0)+SETTINGS!$B$30*IF(ISNUMBER($P13),$P13,0)+SETTINGS!$B$31*IF(ISNUMBER($T13),$T13,0)+SETTINGS!$B$32*IF(ISNUMBER($X13),$X13,0))/$Y13)) | AA13: =IF($A13="","",COUNT($D13,$H13,$L13,$Q13,$U13)) | AB13: =IF($A13="","",IF($AA13<=1,"SINGLE-SOURCE / LOW CONFIDENCE","")) | AC13: =IF($A13="","",IF(AND($C13="FBS-RECLASSIFYING",ISNUMBER($L13),$L13<0),"NO-AUTO-UPGRADE GUARD APPLIED",""))
A14: =IF('TEAM MAP'!$A14="","",'TEAM MAP'!$A14) | B14: =IF('TEAM MAP'!$A14="","",'TEAM MAP'!$B14) | C14: =IF('TEAM MAP'!$A14="","",'TEAM MAP'!$D14) | D14: 14.8 | E14: 46108 | F14: https://www.espn.com/college-football/story/_/id/48306284/2026-college-football-sp+-rankings-138-fbs-teams | G14: =IF($D14="","",$D14-AVERAGE($D$6:$D$143)) | H14: 12.2 | I14: 46222 | J14: https://www.espn.com/college-football/fpi | K14: =IF($H14="","",$H14-AVERAGE($H$6:$H$143)) | M14: =IF($L14="","",IF($C14="FBS-RECLASSIFYING",IF($L14<0,$L14,$L14*(1-SETTINGS!$B$16)),$L14*(1-SETTINGS!$B$15))) | P14: =IF($M14="","",$M14-AVERAGE($M$6:$M$143)) | Q14: 15.4 | R14: 46222 | S14: https://www.teamrankings.com/college-football/ranking/predictive-by-other | T14: =IF($Q14="","",$Q14-AVERAGE($Q$6:$Q$143)) | X14: =IF($U14="","",$U14-AVERAGE($U$6:$U$143)) | Y14: =IF($A14="","",SETTINGS!$B$28*ISNUMBER($G14)+SETTINGS!$B$29*ISNUMBER($K14)+SETTINGS!$B$30*ISNUMBER($P14)+SETTINGS!$B$31*ISNUMBER($T14)+SETTINGS!$B$32*ISNUMBER($X14)) | Z14: =IF($A14="","",IF($Y14=0,"",(SETTINGS!$B$28*IF(ISNUMBER($G14),$G14,0)+SETTINGS!$B$29*IF(ISNUMBER($K14),$K14,0)+SETTINGS!$B$30*IF(ISNUMBER($P14),$P14,0)+SETTINGS!$B$31*IF(ISNUMBER($T14),$T14,0)+SETTINGS!$B$32*IF(ISNUMBER($X14),$X14,0))/$Y14)) | AA14: =IF($A14="","",COUNT($D14,$H14,$L14,$Q14,$U14)) | AB14: =IF($A14="","",IF($AA14<=1,"SINGLE-SOURCE / LOW CONFIDENCE","")) | AC14: =IF($A14="","",IF(AND($C14="FBS-RECLASSIFYING",ISNUMBER($L14),$L14<0),"NO-AUTO-UPGRADE GUARD APPLIED",""))
A15: =IF('TEAM MAP'!$A15="","",'TEAM MAP'!$A15) | B15: =IF('TEAM MAP'!$A15="","",'TEAM MAP'!$B15) | C15: =IF('TEAM MAP'!$A15="","",'TEAM MAP'!$D15) | D15: 17.2 | E15: 46108 | F15: https://www.espn.com/college-football/story/_/id/48306284/2026-college-football-sp+-rankings-138-fbs-teams | G15: =IF($D15="","",$D15-AVERAGE($D$6:$D$143)) | H15: 17.8 | I15: 46222 | J15: https://www.espn.com/college-football/fpi | K15: =IF($H15="","",$H15-AVERAGE($H$6:$H$143)) | M15: =IF($L15="","",IF($C15="FBS-RECLASSIFYING",IF($L15<0,$L15,$L15*(1-SETTINGS!$B$16)),$L15*(1-SETTINGS!$B$15))) | P15: =IF($M15="","",$M15-AVERAGE($M$6:$M$143)) | Q15: 22 | R15: 46222 | S15: https://www.teamrankings.com/college-football/ranking/predictive-by-other | T15: =IF($Q15="","",$Q15-AVERAGE($Q$6:$Q$143)) | X15: =IF($U15="","",$U15-AVERAGE($U$6:$U$143)) | Y15: =IF($A15="","",SETTINGS!$B$28*ISNUMBER($G15)+SETTINGS!$B$29*ISNUMBER($K15)+SETTINGS!$B$30*ISNUMBER($P15)+SETTINGS!$B$31*ISNUMBER($T15)+SETTINGS!$B$32*ISNUMBER($X15)) | Z15: =IF($A15="","",IF($Y15=0,"",(SETTINGS!$B$28*IF(ISNUMBER($G15),$G15,0)+SETTINGS!$B$29*IF(ISNUMBER($K15),$K15,0)+SETTINGS!$B$30*IF(ISNUMBER($P15),$P15,0)+SETTINGS!$B$31*IF(ISNUMBER($T15),$T15,0)+SETTINGS!$B$32*IF(ISNUMBER($X15),$X15,0))/$Y15)) | AA15: =IF($A15="","",COUNT($D15,$H15,$L15,$Q15,$U15)) | AB15: =IF($A15="","",IF($AA15<=1,"SINGLE-SOURCE / LOW CONFIDENCE","")) | AC15: =IF($A15="","",IF(AND($C15="FBS-RECLASSIFYING",ISNUMBER($L15),$L15<0),"NO-AUTO-UPGRADE GUARD APPLIED",""))
A16: =IF('TEAM MAP'!$A16="","",'TEAM MAP'!$A16) | B16: =IF('TEAM MAP'!$A16="","",'TEAM MAP'!$B16) | C16: =IF('TEAM MAP'!$A16="","",'TEAM MAP'!$D16) | D16: 15.9 | E16: 46108 | F16: https://www.espn.com/college-football/story/_/id/48306284/2026-college-football-sp+-rankings-138-fbs-teams | G16: =IF($D16="","",$D16-AVERAGE($D$6:$D$143)) | H16: 16 | I16: 46222 | J16: https://www.espn.com/college-football/fpi | K16: =IF($H16="","",$H16-AVERAGE($H$6:$H$143)) | M16: =IF($L16="","",IF($C16="FBS-RECLASSIFYING",IF($L16<0,$L16,$L16*(1-SETTINGS!$B$16)),$L16*(1-SETTINGS!$B$15))) | P16: =IF($M16="","",$M16-AVERAGE($M$6:$M$143)) | Q16: 22.3 | R16: 46222 | S16: https://www.teamrankings.com/college-football/ranking/predictive-by-other | T16: =IF($Q16="","",$Q16-AVERAGE($Q$6:$Q$143)) | X16: =IF($U16="","",$U16-AVERAGE($U$6:$U$143)) | Y16: =IF($A16="","",SETTINGS!$B$28*ISNUMBER($G16)+SETTINGS!$B$29*ISNUMBER($K16)+SETTINGS!$B$30*ISNUMBER($P16)+SETTINGS!$B$31*ISNUMBER($T16)+SETTINGS!$B$32*ISNUMBER($X16)) | Z16: =IF($A16="","",IF($Y16=0,"",(SETTINGS!$B$28*IF(ISNUMBER($G16),$G16,0)+SETTINGS!$B$29*IF(ISNUMBER($K16),$K16,0)+SETTINGS!$B$30*IF(ISNUMBER($P16),$P16,0)+SETTINGS!$B$31*IF(ISNUMBER($T16),$T16,0)+SETTINGS!$B$32*IF(ISNUMBER($X16),$X16,0))/$Y16)) | AA16: =IF($A16="","",COUNT($D16,$H16,$L16,$Q16,$U16)) | AB16: =IF($A16="","",IF($AA16<=1,"SINGLE-SOURCE / LOW CONFIDENCE","")) | AC16: =IF($A16="","",IF(AND($C16="FBS-RECLASSIFYING",ISNUMBER($L16),$L16<0),"NO-AUTO-UPGRADE GUARD APPLIED",""))
A17: =IF('TEAM MAP'!$A17="","",'TEAM MAP'!$A17) | B17: =IF('TEAM MAP'!$A17="","",'TEAM MAP'!$B17) | C17: =IF('TEAM MAP'!$A17="","",'TEAM MAP'!$D17) | D17: 12.1 | E17: 46108 | F17: https://www.espn.com/college-football/story/_/id/48306284/2026-college-football-sp+-rankings-138-fbs-teams | G17: =IF($D17="","",$D17-AVERAGE($D$6:$D$143)) | H17: 11.7 | I17: 46222 | J17: https://www.espn.com/college-football/fpi | K17: =IF($H17="","",$H17-AVERAGE($H$6:$H$143)) | M17: =IF($L17="","",IF($C17="FBS-RECLASSIFYING",IF($L17<0,$L17,$L17*(1-SETTINGS!$B$16)),$L17*(1-SETTINGS!$B$15))) | P17: =IF($M17="","",$M17-AVERAGE($M$6:$M$143)) | Q17: 12.2 | R17: 46222 | S17: https://www.teamrankings.com/college-football/ranking/predictive-by-other | T17: =IF($Q17="","",$Q17-AVERAGE($Q$6:$Q$143)) | X17: =IF($U17="","",$U17-AVERAGE($U$6:$U$143)) | Y17: =IF($A17="","",SETTINGS!$B$28*ISNUMBER($G17)+SETTINGS!$B$29*ISNUMBER($K17)+SETTINGS!$B$30*ISNUMBER($P17)+SETTINGS!$B$31*ISNUMBER($T17)+SETTINGS!$B$32*ISNUMBER($X17)) | Z17: =IF($A17="","",IF($Y17=0,"",(SETTINGS!$B$28*IF(ISNUMBER($G17),$G17,0)+SETTINGS!$B$29*IF(ISNUMBER($K17),$K17,0)+SETTINGS!$B$30*IF(ISNUMBER($P17),$P17,0)+SETTINGS!$B$31*IF(ISNUMBER($T17),$T17,0)+SETTINGS!$B$32*IF(ISNUMBER($X17),$X17,0))/$Y17)) | AA17: =IF($A17="","",COUNT($D17,$H17,$L17,$Q17,$U17)) | AB17: =IF($A17="","",IF($AA17<=1,"SINGLE-SOURCE / LOW CONFIDENCE","")) | AC17: =IF($A17="","",IF(AND($C17="FBS-RECLASSIFYING",ISNUMBER($L17),$L17<0),"NO-AUTO-UPGRADE GUARD APPLIED",""))
... A143: =IF('TEAM MAP'!$A143="","",'TEAM MAP'!$A143) | B143: =IF('TEAM MAP'!$A143="","",'TEAM MAP'!$B143) | C143: =IF('TEAM MAP'!$A143="","",'TEAM MAP'!$D143) | D143: -11.2 | E143: 46108 | F143: https://www.espn.com/college-football/story/_/id/48306284/2026-college-football-sp+-rankings-138-fbs-teams | G143: =IF($D143="","",$D143-AVERAGE($D$6:$D$143)) | H143: -11.2 | I143: 46222 | J143: https://www.espn.com/college-football/fpi | K143: =IF($H143="","",$H143-AVERAGE($H$6:$H$143)) | M143: =IF($L143="","",IF($C143="FBS-RECLASSIFYING",IF($L143<0,$L143,$L143*(1-SETTINGS!$B$16)),$L143*(1-SETTINGS!$B$15))) | P143: =IF($M143="","",$M143-AVERAGE($M$6:$M$143)) | Q143: -10.9 | R143: 46222 | S143: https://www.teamrankings.com/college-football/ranking/predictive-by-other | T143: =IF($Q143="","",$Q143-AVERAGE($Q$6:$Q$143)) | X143: =IF($U143="","",$U143-AVERAGE($U$6:$U$143)) | Y143: =IF($A143="","",SETTINGS!$B$28*ISNUMBER($G143)+SETTINGS!$B$29*ISNUMBER($K143)+SETTINGS!$B$30*ISNUMBER($P143)+SETTINGS!$B$31*ISNUMBER($T143)+SETTINGS!$B$32*ISNUMBER($X143)) | Z143: =IF($A143="","",IF($Y143=0,"",(SETTINGS!$B$28*IF(ISNUMBER($G143),$G143,0)+SETTINGS!$B$29*IF(ISNUMBER($K143),$K143,0)+SETTINGS!$B$30*IF(ISNUMBER($P143),$P143,0)+SETTINGS!$B$31*IF(ISNUMBER($T143),$T143,0)+SETTINGS!$B$32*IF(ISNUMBER($X143),$X143,0))/$Y143)) | AA143: =IF($A143="","",COUNT($D143,$H143,$L143,$Q143,$U143)) | AB143: =IF($A143="","",IF($AA143<=1,"SINGLE-SOURCE / LOW CONFIDENCE","")) | AC143: =IF($A143="","",IF(AND($C143="FBS-RECLASSIFYING",ISNUMBER($L143),$L143<0),"NO-AUTO-UPGRADE GUARD APPLIED",""))

Sheet TEAM RATINGS
A6: =IF('TEAM MAP'!$A6="","",'TEAM MAP'!$A6) | B6: =IF('TEAM MAP'!$A6="","",'TEAM MAP'!$B6) | C6: =IF('TEAM MAP'!$A6="","",'TEAM MAP'!$C6) | D6: =IF('TEAM MAP'!$A6="","",'TEAM MAP'!$E6) | E6: =IF($A6="","",IF(ISNA(MATCH($A6,PRESEASON!$A$6:$A$143,0)),"",IF(INDEX(PRESEASON!$Z$6:$Z$143,MATCH($A6,PRESEASON!$A$6:$A$143,0))="","",INDEX(PRESEASON!$Z$6:$Z$143,MATCH($A6,PRESEASON!$A$6:$A$143,0))))) | F6: =IF($A6="","",SUMIFS(CLEAN!$AB$6:$AB$1005,CLEAN!$P$6:$P$1005,$A6)+SUMIFS(CLEAN!$AC$6:$AC$1005,CLEAN!$N$6:$N$1005,$A6)) | G6: =IF(OR($A6="",$F6=""),"",IF(MIN($F6,9)>=9,SETTINGS!$C$46,INDEX(SETTINGS!$C$37:$C$46,INT(MIN($F6,9))+1)+(MIN($F6,9)-INT(MIN($F6,9)))*(INDEX(SETTINGS!$C$37:$C$46,INT(MIN($F6,9))+2)-INDEX(SETTINGS!$C$37:$C$46,INT(MIN($F6,9))+1)))) | H6: =IF($A6="","",IF(ISNA(MATCH($A6,CALC!$A$6:$A$143,0)),"",IF(INDEX(CALC!$H$6:$H$143,MATCH($A6,CALC!$A$6:$A$143,0))="","",INDEX(CALC!$H$6:$H$143,MATCH($A6,CALC!$A$6:$A$143,0))))) | I6: =IF($E6="","",IF(OR($H6="",$F6=0,$F6=""),$E6,$G6*$E6+(1-$G6)*$H6)) | J6: =IF(OR($A6="",SETTINGS!$B$4="",SETTINGS!$B$4<=1),"",IF(COUNTIFS(HISTORY!$A$6:$A$3005,SETTINGS!$B$4-1,HISTORY!$B$6:$B$3005,$A6)=1,SUMIFS(HISTORY!$C$6:$C$3005,HISTORY!$A$6:$A$3005,SETTINGS!$B$4-1,HISTORY!$B$6:$B$3005,$A6),"")) | K6: =IF($I6="","",IF(ISNUMBER($J6),$J6+MAX(-SETTINGS!$B$12,MIN(SETTINGS!$B$12,$I6-$J6)),$I6)) | O6: =IF($A6="","",IF(ISNUMBER($L6),$L6,IF($K6="","",$K6))) | P6: =IF($A6="","",IF(ISNUMBER($L6),"OVERRIDE","MODEL")) | Q6: =IF($A6="","",SETTINGS!$B$6) | S6: =IF($A6="","",IF(ISNUMBER($R6),$R6,$Q6)) | W6: =IF($A6="","",SUMIFS(CLEAN!$AD$6:$AD$1005,CLEAN!$P$6:$P$1005,$A6)+SUMIFS(CLEAN!$AE$6:$AE$1005,CLEAN!$N$6:$N$1005,$A6))
A7: =IF('TEAM MAP'!$A7="","",'TEAM MAP'!$A7) | B7: =IF('TEAM MAP'!$A7="","",'TEAM MAP'!$B7) | C7: =IF('TEAM MAP'!$A7="","",'TEAM MAP'!$C7) | D7: =IF('TEAM MAP'!$A7="","",'TEAM MAP'!$E7) | E7: =IF($A7="","",IF(ISNA(MATCH($A7,PRESEASON!$A$6:$A$143,0)),"",IF(INDEX(PRESEASON!$Z$6:$Z$143,MATCH($A7,PRESEASON!$A$6:$A$143,0))="","",INDEX(PRESEASON!$Z$6:$Z$143,MATCH($A7,PRESEASON!$A$6:$A$143,0))))) | F7: =IF($A7="","",SUMIFS(CLEAN!$AB$6:$AB$1005,CLEAN!$P$6:$P$1005,$A7)+SUMIFS(CLEAN!$AC$6:$AC$1005,CLEAN!$N$6:$N$1005,$A7)) | G7: =IF(OR($A7="",$F7=""),"",IF(MIN($F7,9)>=9,SETTINGS!$C$46,INDEX(SETTINGS!$C$37:$C$46,INT(MIN($F7,9))+1)+(MIN($F7,9)-INT(MIN($F7,9)))*(INDEX(SETTINGS!$C$37:$C$46,INT(MIN($F7,9))+2)-INDEX(SETTINGS!$C$37:$C$46,INT(MIN($F7,9))+1)))) | H7: =IF($A7="","",IF(ISNA(MATCH($A7,CALC!$A$6:$A$143,0)),"",IF(INDEX(CALC!$H$6:$H$143,MATCH($A7,CALC!$A$6:$A$143,0))="","",INDEX(CALC!$H$6:$H$143,MATCH($A7,CALC!$A$6:$A$143,0))))) | I7: =IF($E7="","",IF(OR($H7="",$F7=0,$F7=""),$E7,$G7*$E7+(1-$G7)*$H7)) | J7: =IF(OR($A7="",SETTINGS!$B$4="",SETTINGS!$B$4<=1),"",IF(COUNTIFS(HISTORY!$A$6:$A$3005,SETTINGS!$B$4-1,HISTORY!$B$6:$B$3005,$A7)=1,SUMIFS(HISTORY!$C$6:$C$3005,HISTORY!$A$6:$A$3005,SETTINGS!$B$4-1,HISTORY!$B$6:$B$3005,$A7),"")) | K7: =IF($I7="","",IF(ISNUMBER($J7),$J7+MAX(-SETTINGS!$B$12,MIN(SETTINGS!$B$12,$I7-$J7)),$I7)) | O7: =IF($A7="","",IF(ISNUMBER($L7),$L7,IF($K7="","",$K7))) | P7: =IF($A7="","",IF(ISNUMBER($L7),"OVERRIDE","MODEL")) | Q7: =IF($A7="","",SETTINGS!$B$6) | S7: =IF($A7="","",IF(ISNUMBER($R7),$R7,$Q7)) | W7: =IF($A7="","",SUMIFS(CLEAN!$AD$6:$AD$1005,CLEAN!$P$6:$P$1005,$A7)+SUMIFS(CLEAN!$AE$6:$AE$1005,CLEAN!$N$6:$N$1005,$A7))
A8: =IF('TEAM MAP'!$A8="","",'TEAM MAP'!$A8) | B8: =IF('TEAM MAP'!$A8="","",'TEAM MAP'!$B8) | C8: =IF('TEAM MAP'!$A8="","",'TEAM MAP'!$C8) | D8: =IF('TEAM MAP'!$A8="","",'TEAM MAP'!$E8) | E8: =IF($A8="","",IF(ISNA(MATCH($A8,PRESEASON!$A$6:$A$143,0)),"",IF(INDEX(PRESEASON!$Z$6:$Z$143,MATCH($A8,PRESEASON!$A$6:$A$143,0))="","",INDEX(PRESEASON!$Z$6:$Z$143,MATCH($A8,PRESEASON!$A$6:$A$143,0))))) | F8: =IF($A8="","",SUMIFS(CLEAN!$AB$6:$AB$1005,CLEAN!$P$6:$P$1005,$A8)+SUMIFS(CLEAN!$AC$6:$AC$1005,CLEAN!$N$6:$N$1005,$A8)) | G8: =IF(OR($A8="",$F8=""),"",IF(MIN($F8,9)>=9,SETTINGS!$C$46,INDEX(SETTINGS!$C$37:$C$46,INT(MIN($F8,9))+1)+(MIN($F8,9)-INT(MIN($F8,9)))*(INDEX(SETTINGS!$C$37:$C$46,INT(MIN($F8,9))+2)-INDEX(SETTINGS!$C$37:$C$46,INT(MIN($F8,9))+1)))) | H8: =IF($A8="","",IF(ISNA(MATCH($A8,CALC!$A$6:$A$143,0)),"",IF(INDEX(CALC!$H$6:$H$143,MATCH($A8,CALC!$A$6:$A$143,0))="","",INDEX(CALC!$H$6:$H$143,MATCH($A8,CALC!$A$6:$A$143,0))))) | I8: =IF($E8="","",IF(OR($H8="",$F8=0,$F8=""),$E8,$G8*$E8+(1-$G8)*$H8)) | J8: =IF(OR($A8="",SETTINGS!$B$4="",SETTINGS!$B$4<=1),"",IF(COUNTIFS(HISTORY!$A$6:$A$3005,SETTINGS!$B$4-1,HISTORY!$B$6:$B$3005,$A8)=1,SUMIFS(HISTORY!$C$6:$C$3005,HISTORY!$A$6:$A$3005,SETTINGS!$B$4-1,HISTORY!$B$6:$B$3005,$A8),"")) | K8: =IF($I8="","",IF(ISNUMBER($J8),$J8+MAX(-SETTINGS!$B$12,MIN(SETTINGS!$B$12,$I8-$J8)),$I8)) | O8: =IF($A8="","",IF(ISNUMBER($L8),$L8,IF($K8="","",$K8))) | P8: =IF($A8="","",IF(ISNUMBER($L8),"OVERRIDE","MODEL")) | Q8: =IF($A8="","",SETTINGS!$B$6) | S8: =IF($A8="","",IF(ISNUMBER($R8),$R8,$Q8)) | W8: =IF($A8="","",SUMIFS(CLEAN!$AD$6:$AD$1005,CLEAN!$P$6:$P$1005,$A8)+SUMIFS(CLEAN!$AE$6:$AE$1005,CLEAN!$N$6:$N$1005,$A8))
A9: =IF('TEAM MAP'!$A9="","",'TEAM MAP'!$A9) | B9: =IF('TEAM MAP'!$A9="","",'TEAM MAP'!$B9) | C9: =IF('TEAM MAP'!$A9="","",'TEAM MAP'!$C9) | D9: =IF('TEAM MAP'!$A9="","",'TEAM MAP'!$E9) | E9: =IF($A9="","",IF(ISNA(MATCH($A9,PRESEASON!$A$6:$A$143,0)),"",IF(INDEX(PRESEASON!$Z$6:$Z$143,MATCH($A9,PRESEASON!$A$6:$A$143,0))="","",INDEX(PRESEASON!$Z$6:$Z$143,MATCH($A9,PRESEASON!$A$6:$A$143,0))))) | F9: =IF($A9="","",SUMIFS(CLEAN!$AB$6:$AB$1005,CLEAN!$P$6:$P$1005,$A9)+SUMIFS(CLEAN!$AC$6:$AC$1005,CLEAN!$N$6:$N$1005,$A9)) | G9: =IF(OR($A9="",$F9=""),"",IF(MIN($F9,9)>=9,SETTINGS!$C$46,INDEX(SETTINGS!$C$37:$C$46,INT(MIN($F9,9))+1)+(MIN($F9,9)-INT(MIN($F9,9)))*(INDEX(SETTINGS!$C$37:$C$46,INT(MIN($F9,9))+2)-INDEX(SETTINGS!$C$37:$C$46,INT(MIN($F9,9))+1)))) | H9: =IF($A9="","",IF(ISNA(MATCH($A9,CALC!$A$6:$A$143,0)),"",IF(INDEX(CALC!$H$6:$H$143,MATCH($A9,CALC!$A$6:$A$143,0))="","",INDEX(CALC!$H$6:$H$143,MATCH($A9,CALC!$A$6:$A$143,0))))) | I9: =IF($E9="","",IF(OR($H9="",$F9=0,$F9=""),$E9,$G9*$E9+(1-$G9)*$H9)) | J9: =IF(OR($A9="",SETTINGS!$B$4="",SETTINGS!$B$4<=1),"",IF(COUNTIFS(HISTORY!$A$6:$A$3005,SETTINGS!$B$4-1,HISTORY!$B$6:$B$3005,$A9)=1,SUMIFS(HISTORY!$C$6:$C$3005,HISTORY!$A$6:$A$3005,SETTINGS!$B$4-1,HISTORY!$B$6:$B$3005,$A9),"")) | K9: =IF($I9="","",IF(ISNUMBER($J9),$J9+MAX(-SETTINGS!$B$12,MIN(SETTINGS!$B$12,$I9-$J9)),$I9)) | O9: =IF($A9="","",IF(ISNUMBER($L9),$L9,IF($K9="","",$K9))) | P9: =IF($A9="","",IF(ISNUMBER($L9),"OVERRIDE","MODEL")) | Q9: =IF($A9="","",SETTINGS!$B$6) | S9: =IF($A9="","",IF(ISNUMBER($R9),$R9,$Q9)) | W9: =IF($A9="","",SUMIFS(CLEAN!$AD$6:$AD$1005,CLEAN!$P$6:$P$1005,$A9)+SUMIFS(CLEAN!$AE$6:$AE$1005,CLEAN!$N$6:$N$1005,$A9))
A10: =IF('TEAM MAP'!$A10="","",'TEAM MAP'!$A10) | B10: =IF('TEAM MAP'!$A10="","",'TEAM MAP'!$B10) | C10: =IF('TEAM MAP'!$A10="","",'TEAM MAP'!$C10) | D10: =IF('TEAM MAP'!$A10="","",'TEAM MAP'!$E10) | E10: =IF($A10="","",IF(ISNA(MATCH($A10,PRESEASON!$A$6:$A$143,0)),"",IF(INDEX(PRESEASON!$Z$6:$Z$143,MATCH($A10,PRESEASON!$A$6:$A$143,0))="","",INDEX(PRESEASON!$Z$6:$Z$143,MATCH($A10,PRESEASON!$A$6:$A$143,0))))) | F10: =IF($A10="","",SUMIFS(CLEAN!$AB$6:$AB$1005,CLEAN!$P$6:$P$1005,$A10)+SUMIFS(CLEAN!$AC$6:$AC$1005,CLEAN!$N$6:$N$1005,$A10)) | G10: =IF(OR($A10="",$F10=""),"",IF(MIN($F10,9)>=9,SETTINGS!$C$46,INDEX(SETTINGS!$C$37:$C$46,INT(MIN($F10,9))+1)+(MIN($F10,9)-INT(MIN($F10,9)))*(INDEX(SETTINGS!$C$37:$C$46,INT(MIN($F10,9))+2)-INDEX(SETTINGS!$C$37:$C$46,INT(MIN($F10,9))+1)))) | H10: =IF($A10="","",IF(ISNA(MATCH($A10,CALC!$A$6:$A$143,0)),"",IF(INDEX(CALC!$H$6:$H$143,MATCH($A10,CALC!$A$6:$A$143,0))="","",INDEX(CALC!$H$6:$H$143,MATCH($A10,CALC!$A$6:$A$143,0))))) | I10: =IF($E10="","",IF(OR($H10="",$F10=0,$F10=""),$E10,$G10*$E10+(1-$G10)*$H10)) | J10: =IF(OR($A10="",SETTINGS!$B$4="",SETTINGS!$B$4<=1),"",IF(COUNTIFS(HISTORY!$A$6:$A$3005,SETTINGS!$B$4-1,HISTORY!$B$6:$B$3005,$A10)=1,SUMIFS(HISTORY!$C$6:$C$3005,HISTORY!$A$6:$A$3005,SETTINGS!$B$4-1,HISTORY!$B$6:$B$3005,$A10),"")) | K10: =IF($I10="","",IF(ISNUMBER($J10),$J10+MAX(-SETTINGS!$B$12,MIN(SETTINGS!$B$12,$I10-$J10)),$I10)) | O10: =IF($A10="","",IF(ISNUMBER($L10),$L10,IF($K10="","",$K10))) | P10: =IF($A10="","",IF(ISNUMBER($L10),"OVERRIDE","MODEL")) | Q10: =IF($A10="","",SETTINGS!$B$6) | S10: =IF($A10="","",IF(ISNUMBER($R10),$R10,$Q10)) | W10: =IF($A10="","",SUMIFS(CLEAN!$AD$6:$AD$1005,CLEAN!$P$6:$P$1005,$A10)+SUMIFS(CLEAN!$AE$6:$AE$1005,CLEAN!$N$6:$N$1005,$A10))
A11: =IF('TEAM MAP'!$A11="","",'TEAM MAP'!$A11) | B11: =IF('TEAM MAP'!$A11="","",'TEAM MAP'!$B11) | C11: =IF('TEAM MAP'!$A11="","",'TEAM MAP'!$C11) | D11: =IF('TEAM MAP'!$A11="","",'TEAM MAP'!$E11) | E11: =IF($A11="","",IF(ISNA(MATCH($A11,PRESEASON!$A$6:$A$143,0)),"",IF(INDEX(PRESEASON!$Z$6:$Z$143,MATCH($A11,PRESEASON!$A$6:$A$143,0))="","",INDEX(PRESEASON!$Z$6:$Z$143,MATCH($A11,PRESEASON!$A$6:$A$143,0))))) | F11: =IF($A11="","",SUMIFS(CLEAN!$AB$6:$AB$1005,CLEAN!$P$6:$P$1005,$A11)+SUMIFS(CLEAN!$AC$6:$AC$1005,CLEAN!$N$6:$N$1005,$A11)) | G11: =IF(OR($A11="",$F11=""),"",IF(MIN($F11,9)>=9,SETTINGS!$C$46,INDEX(SETTINGS!$C$37:$C$46,INT(MIN($F11,9))+1)+(MIN($F11,9)-INT(MIN($F11,9)))*(INDEX(SETTINGS!$C$37:$C$46,INT(MIN($F11,9))+2)-INDEX(SETTINGS!$C$37:$C$46,INT(MIN($F11,9))+1)))) | H11: =IF($A11="","",IF(ISNA(MATCH($A11,CALC!$A$6:$A$143,0)),"",IF(INDEX(CALC!$H$6:$H$143,MATCH($A11,CALC!$A$6:$A$143,0))="","",INDEX(CALC!$H$6:$H$143,MATCH($A11,CALC!$A$6:$A$143,0))))) | I11: =IF($E11="","",IF(OR($H11="",$F11=0,$F11=""),$E11,$G11*$E11+(1-$G11)*$H11)) | J11: =IF(OR($A11="",SETTINGS!$B$4="",SETTINGS!$B$4<=1),"",IF(COUNTIFS(HISTORY!$A$6:$A$3005,SETTINGS!$B$4-1,HISTORY!$B$6:$B$3005,$A11)=1,SUMIFS(HISTORY!$C$6:$C$3005,HISTORY!$A$6:$A$3005,SETTINGS!$B$4-1,HISTORY!$B$6:$B$3005,$A11),"")) | K11: =IF($I11="","",IF(ISNUMBER($J11),$J11+MAX(-SETTINGS!$B$12,MIN(SETTINGS!$B$12,$I11-$J11)),$I11)) | O11: =IF($A11="","",IF(ISNUMBER($L11),$L11,IF($K11="","",$K11))) | P11: =IF($A11="","",IF(ISNUMBER($L11),"OVERRIDE","MODEL")) | Q11: =IF($A11="","",SETTINGS!$B$6) | S11: =IF($A11="","",IF(ISNUMBER($R11),$R11,$Q11)) | W11: =IF($A11="","",SUMIFS(CLEAN!$AD$6:$AD$1005,CLEAN!$P$6:$P$1005,$A11)+SUMIFS(CLEAN!$AE$6:$AE$1005,CLEAN!$N$6:$N$1005,$A11))
A12: =IF('TEAM MAP'!$A12="","",'TEAM MAP'!$A12) | B12: =IF('TEAM MAP'!$A12="","",'TEAM MAP'!$B12) | C12: =IF('TEAM MAP'!$A12="","",'TEAM MAP'!$C12) | D12: =IF('TEAM MAP'!$A12="","",'TEAM MAP'!$E12) | E12: =IF($A12="","",IF(ISNA(MATCH($A12,PRESEASON!$A$6:$A$143,0)),"",IF(INDEX(PRESEASON!$Z$6:$Z$143,MATCH($A12,PRESEASON!$A$6:$A$143,0))="","",INDEX(PRESEASON!$Z$6:$Z$143,MATCH($A12,PRESEASON!$A$6:$A$143,0))))) | F12: =IF($A12="","",SUMIFS(CLEAN!$AB$6:$AB$1005,CLEAN!$P$6:$P$1005,$A12)+SUMIFS(CLEAN!$AC$6:$AC$1005,CLEAN!$N$6:$N$1005,$A12)) | G12: =IF(OR($A12="",$F12=""),"",IF(MIN($F12,9)>=9,SETTINGS!$C$46,INDEX(SETTINGS!$C$37:$C$46,INT(MIN($F12,9))+1)+(MIN($F12,9)-INT(MIN($F12,9)))*(INDEX(SETTINGS!$C$37:$C$46,INT(MIN($F12,9))+2)-INDEX(SETTINGS!$C$37:$C$46,INT(MIN($F12,9))+1)))) | H12: =IF($A12="","",IF(ISNA(MATCH($A12,CALC!$A$6:$A$143,0)),"",IF(INDEX(CALC!$H$6:$H$143,MATCH($A12,CALC!$A$6:$A$143,0))="","",INDEX(CALC!$H$6:$H$143,MATCH($A12,CALC!$A$6:$A$143,0))))) | I12: =IF($E12="","",IF(OR($H12="",$F12=0,$F12=""),$E12,$G12*$E12+(1-$G12)*$H12)) | J12: =IF(OR($A12="",SETTINGS!$B$4="",SETTINGS!$B$4<=1),"",IF(COUNTIFS(HISTORY!$A$6:$A$3005,SETTINGS!$B$4-1,HISTORY!$B$6:$B$3005,$A12)=1,SUMIFS(HISTORY!$C$6:$C$3005,HISTORY!$A$6:$A$3005,SETTINGS!$B$4-1,HISTORY!$B$6:$B$3005,$A12),"")) | K12: =IF($I12="","",IF(ISNUMBER($J12),$J12+MAX(-SETTINGS!$B$12,MIN(SETTINGS!$B$12,$I12-$J12)),$I12)) | O12: =IF($A12="","",IF(ISNUMBER($L12),$L12,IF($K12="","",$K12))) | P12: =IF($A12="","",IF(ISNUMBER($L12),"OVERRIDE","MODEL")) | Q12: =IF($A12="","",SETTINGS!$B$6) | S12: =IF($A12="","",IF(ISNUMBER($R12),$R12,$Q12)) | W12: =IF($A12="","",SUMIFS(CLEAN!$AD$6:$AD$1005,CLEAN!$P$6:$P$1005,$A12)+SUMIFS(CLEAN!$AE$6:$AE$1005,CLEAN!$N$6:$N$1005,$A12))
A13: =IF('TEAM MAP'!$A13="","",'TEAM MAP'!$A13) | B13: =IF('TEAM MAP'!$A13="","",'TEAM MAP'!$B13) | C13: =IF('TEAM MAP'!$A13="","",'TEAM MAP'!$C13) | D13: =IF('TEAM MAP'!$A13="","",'TEAM MAP'!$E13) | E13: =IF($A13="","",IF(ISNA(MATCH($A13,PRESEASON!$A$6:$A$143,0)),"",IF(INDEX(PRESEASON!$Z$6:$Z$143,MATCH($A13,PRESEASON!$A$6:$A$143,0))="","",INDEX(PRESEASON!$Z$6:$Z$143,MATCH($A13,PRESEASON!$A$6:$A$143,0))))) | F13: =IF($A13="","",SUMIFS(CLEAN!$AB$6:$AB$1005,CLEAN!$P$6:$P$1005,$A13)+SUMIFS(CLEAN!$AC$6:$AC$1005,CLEAN!$N$6:$N$1005,$A13)) | G13: =IF(OR($A13="",$F13=""),"",IF(MIN($F13,9)>=9,SETTINGS!$C$46,INDEX(SETTINGS!$C$37:$C$46,INT(MIN($F13,9))+1)+(MIN($F13,9)-INT(MIN($F13,9)))*(INDEX(SETTINGS!$C$37:$C$46,INT(MIN($F13,9))+2)-INDEX(SETTINGS!$C$37:$C$46,INT(MIN($F13,9))+1)))) | H13: =IF($A13="","",IF(ISNA(MATCH($A13,CALC!$A$6:$A$143,0)),"",IF(INDEX(CALC!$H$6:$H$143,MATCH($A13,CALC!$A$6:$A$143,0))="","",INDEX(CALC!$H$6:$H$143,MATCH($A13,CALC!$A$6:$A$143,0))))) | I13: =IF($E13="","",IF(OR($H13="",$F13=0,$F13=""),$E13,$G13*$E13+(1-$G13)*$H13)) | J13: =IF(OR($A13="",SETTINGS!$B$4="",SETTINGS!$B$4<=1),"",IF(COUNTIFS(HISTORY!$A$6:$A$3005,SETTINGS!$B$4-1,HISTORY!$B$6:$B$3005,$A13)=1,SUMIFS(HISTORY!$C$6:$C$3005,HISTORY!$A$6:$A$3005,SETTINGS!$B$4-1,HISTORY!$B$6:$B$3005,$A13),"")) | K13: =IF($I13="","",IF(ISNUMBER($J13),$J13+MAX(-SETTINGS!$B$12,MIN(SETTINGS!$B$12,$I13-$J13)),$I13)) | O13: =IF($A13="","",IF(ISNUMBER($L13),$L13,IF($K13="","",$K13))) | P13: =IF($A13="","",IF(ISNUMBER($L13),"OVERRIDE","MODEL")) | Q13: =IF($A13="","",SETTINGS!$B$6) | S13: =IF($A13="","",IF(ISNUMBER($R13),$R13,$Q13)) | W13: =IF($A13="","",SUMIFS(CLEAN!$AD$6:$AD$1005,CLEAN!$P$6:$P$1005,$A13)+SUMIFS(CLEAN!$AE$6:$AE$1005,CLEAN!$N$6:$N$1005,$A13))
A14: =IF('TEAM MAP'!$A14="","",'TEAM MAP'!$A14) | B14: =IF('TEAM MAP'!$A14="","",'TEAM MAP'!$B14) | C14: =IF('TEAM MAP'!$A14="","",'TEAM MAP'!$C14) | D14: =IF('TEAM MAP'!$A14="","",'TEAM MAP'!$E14) | E14: =IF($A14="","",IF(ISNA(MATCH($A14,PRESEASON!$A$6:$A$143,0)),"",IF(INDEX(PRESEASON!$Z$6:$Z$143,MATCH($A14,PRESEASON!$A$6:$A$143,0))="","",INDEX(PRESEASON!$Z$6:$Z$143,MATCH($A14,PRESEASON!$A$6:$A$143,0))))) | F14: =IF($A14="","",SUMIFS(CLEAN!$AB$6:$AB$1005,CLEAN!$P$6:$P$1005,$A14)+SUMIFS(CLEAN!$AC$6:$AC$1005,CLEAN!$N$6:$N$1005,$A14)) | G14: =IF(OR($A14="",$F14=""),"",IF(MIN($F14,9)>=9,SETTINGS!$C$46,INDEX(SETTINGS!$C$37:$C$46,INT(MIN($F14,9))+1)+(MIN($F14,9)-INT(MIN($F14,9)))*(INDEX(SETTINGS!$C$37:$C$46,INT(MIN($F14,9))+2)-INDEX(SETTINGS!$C$37:$C$46,INT(MIN($F14,9))+1)))) | H14: =IF($A14="","",IF(ISNA(MATCH($A14,CALC!$A$6:$A$143,0)),"",IF(INDEX(CALC!$H$6:$H$143,MATCH($A14,CALC!$A$6:$A$143,0))="","",INDEX(CALC!$H$6:$H$143,MATCH($A14,CALC!$A$6:$A$143,0))))) | I14: =IF($E14="","",IF(OR($H14="",$F14=0,$F14=""),$E14,$G14*$E14+(1-$G14)*$H14)) | J14: =IF(OR($A14="",SETTINGS!$B$4="",SETTINGS!$B$4<=1),"",IF(COUNTIFS(HISTORY!$A$6:$A$3005,SETTINGS!$B$4-1,HISTORY!$B$6:$B$3005,$A14)=1,SUMIFS(HISTORY!$C$6:$C$3005,HISTORY!$A$6:$A$3005,SETTINGS!$B$4-1,HISTORY!$B$6:$B$3005,$A14),"")) | K14: =IF($I14="","",IF(ISNUMBER($J14),$J14+MAX(-SETTINGS!$B$12,MIN(SETTINGS!$B$12,$I14-$J14)),$I14)) | O14: =IF($A14="","",IF(ISNUMBER($L14),$L14,IF($K14="","",$K14))) | P14: =IF($A14="","",IF(ISNUMBER($L14),"OVERRIDE","MODEL")) | Q14: =IF($A14="","",SETTINGS!$B$6) | S14: =IF($A14="","",IF(ISNUMBER($R14),$R14,$Q14)) | W14: =IF($A14="","",SUMIFS(CLEAN!$AD$6:$AD$1005,CLEAN!$P$6:$P$1005,$A14)+SUMIFS(CLEAN!$AE$6:$AE$1005,CLEAN!$N$6:$N$1005,$A14))
A15: =IF('TEAM MAP'!$A15="","",'TEAM MAP'!$A15) | B15: =IF('TEAM MAP'!$A15="","",'TEAM MAP'!$B15) | C15: =IF('TEAM MAP'!$A15="","",'TEAM MAP'!$C15) | D15: =IF('TEAM MAP'!$A15="","",'TEAM MAP'!$E15) | E15: =IF($A15="","",IF(ISNA(MATCH($A15,PRESEASON!$A$6:$A$143,0)),"",IF(INDEX(PRESEASON!$Z$6:$Z$143,MATCH($A15,PRESEASON!$A$6:$A$143,0))="","",INDEX(PRESEASON!$Z$6:$Z$143,MATCH($A15,PRESEASON!$A$6:$A$143,0))))) | F15: =IF($A15="","",SUMIFS(CLEAN!$AB$6:$AB$1005,CLEAN!$P$6:$P$1005,$A15)+SUMIFS(CLEAN!$AC$6:$AC$1005,CLEAN!$N$6:$N$1005,$A15)) | G15: =IF(OR($A15="",$F15=""),"",IF(MIN($F15,9)>=9,SETTINGS!$C$46,INDEX(SETTINGS!$C$37:$C$46,INT(MIN($F15,9))+1)+(MIN($F15,9)-INT(MIN($F15,9)))*(INDEX(SETTINGS!$C$37:$C$46,INT(MIN($F15,9))+2)-INDEX(SETTINGS!$C$37:$C$46,INT(MIN($F15,9))+1)))) | H15: =IF($A15="","",IF(ISNA(MATCH($A15,CALC!$A$6:$A$143,0)),"",IF(INDEX(CALC!$H$6:$H$143,MATCH($A15,CALC!$A$6:$A$143,0))="","",INDEX(CALC!$H$6:$H$143,MATCH($A15,CALC!$A$6:$A$143,0))))) | I15: =IF($E15="","",IF(OR($H15="",$F15=0,$F15=""),$E15,$G15*$E15+(1-$G15)*$H15)) | J15: =IF(OR($A15="",SETTINGS!$B$4="",SETTINGS!$B$4<=1),"",IF(COUNTIFS(HISTORY!$A$6:$A$3005,SETTINGS!$B$4-1,HISTORY!$B$6:$B$3005,$A15)=1,SUMIFS(HISTORY!$C$6:$C$3005,HISTORY!$A$6:$A$3005,SETTINGS!$B$4-1,HISTORY!$B$6:$B$3005,$A15),"")) | K15: =IF($I15="","",IF(ISNUMBER($J15),$J15+MAX(-SETTINGS!$B$12,MIN(SETTINGS!$B$12,$I15-$J15)),$I15)) | O15: =IF($A15="","",IF(ISNUMBER($L15),$L15,IF($K15="","",$K15))) | P15: =IF($A15="","",IF(ISNUMBER($L15),"OVERRIDE","MODEL")) | Q15: =IF($A15="","",SETTINGS!$B$6) | S15: =IF($A15="","",IF(ISNUMBER($R15),$R15,$Q15)) | W15: =IF($A15="","",SUMIFS(CLEAN!$AD$6:$AD$1005,CLEAN!$P$6:$P$1005,$A15)+SUMIFS(CLEAN!$AE$6:$AE$1005,CLEAN!$N$6:$N$1005,$A15))
A16: =IF('TEAM MAP'!$A16="","",'TEAM MAP'!$A16) | B16: =IF('TEAM MAP'!$A16="","",'TEAM MAP'!$B16) | C16: =IF('TEAM MAP'!$A16="","",'TEAM MAP'!$C16) | D16: =IF('TEAM MAP'!$A16="","",'TEAM MAP'!$E16) | E16: =IF($A16="","",IF(ISNA(MATCH($A16,PRESEASON!$A$6:$A$143,0)),"",IF(INDEX(PRESEASON!$Z$6:$Z$143,MATCH($A16,PRESEASON!$A$6:$A$143,0))="","",INDEX(PRESEASON!$Z$6:$Z$143,MATCH($A16,PRESEASON!$A$6:$A$143,0))))) | F16: =IF($A16="","",SUMIFS(CLEAN!$AB$6:$AB$1005,CLEAN!$P$6:$P$1005,$A16)+SUMIFS(CLEAN!$AC$6:$AC$1005,CLEAN!$N$6:$N$1005,$A16)) | G16: =IF(OR($A16="",$F16=""),"",IF(MIN($F16,9)>=9,SETTINGS!$C$46,INDEX(SETTINGS!$C$37:$C$46,INT(MIN($F16,9))+1)+(MIN($F16,9)-INT(MIN($F16,9)))*(INDEX(SETTINGS!$C$37:$C$46,INT(MIN($F16,9))+2)-INDEX(SETTINGS!$C$37:$C$46,INT(MIN($F16,9))+1)))) | H16: =IF($A16="","",IF(ISNA(MATCH($A16,CALC!$A$6:$A$143,0)),"",IF(INDEX(CALC!$H$6:$H$143,MATCH($A16,CALC!$A$6:$A$143,0))="","",INDEX(CALC!$H$6:$H$143,MATCH($A16,CALC!$A$6:$A$143,0))))) | I16: =IF($E16="","",IF(OR($H16="",$F16=0,$F16=""),$E16,$G16*$E16+(1-$G16)*$H16)) | J16: =IF(OR($A16="",SETTINGS!$B$4="",SETTINGS!$B$4<=1),"",IF(COUNTIFS(HISTORY!$A$6:$A$3005,SETTINGS!$B$4-1,HISTORY!$B$6:$B$3005,$A16)=1,SUMIFS(HISTORY!$C$6:$C$3005,HISTORY!$A$6:$A$3005,SETTINGS!$B$4-1,HISTORY!$B$6:$B$3005,$A16),"")) | K16: =IF($I16="","",IF(ISNUMBER($J16),$J16+MAX(-SETTINGS!$B$12,MIN(SETTINGS!$B$12,$I16-$J16)),$I16)) | O16: =IF($A16="","",IF(ISNUMBER($L16),$L16,IF($K16="","",$K16))) | P16: =IF($A16="","",IF(ISNUMBER($L16),"OVERRIDE","MODEL")) | Q16: =IF($A16="","",SETTINGS!$B$6) | S16: =IF($A16="","",IF(ISNUMBER($R16),$R16,$Q16)) | W16: =IF($A16="","",SUMIFS(CLEAN!$AD$6:$AD$1005,CLEAN!$P$6:$P$1005,$A16)+SUMIFS(CLEAN!$AE$6:$AE$1005,CLEAN!$N$6:$N$1005,$A16))
A17: =IF('TEAM MAP'!$A17="","",'TEAM MAP'!$A17) | B17: =IF('TEAM MAP'!$A17="","",'TEAM MAP'!$B17) | C17: =IF('TEAM MAP'!$A17="","",'TEAM MAP'!$C17) | D17: =IF('TEAM MAP'!$A17="","",'TEAM MAP'!$E17) | E17: =IF($A17="","",IF(ISNA(MATCH($A17,PRESEASON!$A$6:$A$143,0)),"",IF(INDEX(PRESEASON!$Z$6:$Z$143,MATCH($A17,PRESEASON!$A$6:$A$143,0))="","",INDEX(PRESEASON!$Z$6:$Z$143,MATCH($A17,PRESEASON!$A$6:$A$143,0))))) | F17: =IF($A17="","",SUMIFS(CLEAN!$AB$6:$AB$1005,CLEAN!$P$6:$P$1005,$A17)+SUMIFS(CLEAN!$AC$6:$AC$1005,CLEAN!$N$6:$N$1005,$A17)) | G17: =IF(OR($A17="",$F17=""),"",IF(MIN($F17,9)>=9,SETTINGS!$C$46,INDEX(SETTINGS!$C$37:$C$46,INT(MIN($F17,9))+1)+(MIN($F17,9)-INT(MIN($F17,9)))*(INDEX(SETTINGS!$C$37:$C$46,INT(MIN($F17,9))+2)-INDEX(SETTINGS!$C$37:$C$46,INT(MIN($F17,9))+1)))) | H17: =IF($A17="","",IF(ISNA(MATCH($A17,CALC!$A$6:$A$143,0)),"",IF(INDEX(CALC!$H$6:$H$143,MATCH($A17,CALC!$A$6:$A$143,0))="","",INDEX(CALC!$H$6:$H$143,MATCH($A17,CALC!$A$6:$A$143,0))))) | I17: =IF($E17="","",IF(OR($H17="",$F17=0,$F17=""),$E17,$G17*$E17+(1-$G17)*$H17)) | J17: =IF(OR($A17="",SETTINGS!$B$4="",SETTINGS!$B$4<=1),"",IF(COUNTIFS(HISTORY!$A$6:$A$3005,SETTINGS!$B$4-1,HISTORY!$B$6:$B$3005,$A17)=1,SUMIFS(HISTORY!$C$6:$C$3005,HISTORY!$A$6:$A$3005,SETTINGS!$B$4-1,HISTORY!$B$6:$B$3005,$A17),"")) | K17: =IF($I17="","",IF(ISNUMBER($J17),$J17+MAX(-SETTINGS!$B$12,MIN(SETTINGS!$B$12,$I17-$J17)),$I17)) | O17: =IF($A17="","",IF(ISNUMBER($L17),$L17,IF($K17="","",$K17))) | P17: =IF($A17="","",IF(ISNUMBER($L17),"OVERRIDE","MODEL")) | Q17: =IF($A17="","",SETTINGS!$B$6) | S17: =IF($A17="","",IF(ISNUMBER($R17),$R17,$Q17)) | W17: =IF($A17="","",SUMIFS(CLEAN!$AD$6:$AD$1005,CLEAN!$P$6:$P$1005,$A17)+SUMIFS(CLEAN!$AE$6:$AE$1005,CLEAN!$N$6:$N$1005,$A17))
... A143: =IF('TEAM MAP'!$A143="","",'TEAM MAP'!$A143) | B143: =IF('TEAM MAP'!$A143="","",'TEAM MAP'!$B143) | C143: =IF('TEAM MAP'!$A143="","",'TEAM MAP'!$C143) | D143: =IF('TEAM MAP'!$A143="","",'TEAM MAP'!$E143) | E143: =IF($A143="","",IF(ISNA(MATCH($A143,PRESEASON!$A$6:$A$143,0)),"",IF(INDEX(PRESEASON!$Z$6:$Z$143,MATCH($A143,PRESEASON!$A$6:$A$143,0))="","",INDEX(PRESEASON!$Z$6:$Z$143,MATCH($A143,PRESEASON!$A$6:$A$143,0))))) | F143: =IF($A143="","",SUMIFS(CLEAN!$AB$6:$AB$1005,CLEAN!$P$6:$P$1005,$A143)+SUMIFS(CLEAN!$AC$6:$AC$1005,CLEAN!$N$6:$N$1005,$A143)) | G143: =IF(OR($A143="",$F143=""),"",IF(MIN($F143,9)>=9,SETTINGS!$C$46,INDEX(SETTINGS!$C$37:$C$46,INT(MIN($F143,9))+1)+(MIN($F143,9)-INT(MIN($F143,9)))*(INDEX(SETTINGS!$C$37:$C$46,INT(MIN($F143,9))+2)-INDEX(SETTINGS!$C$37:$C$46,INT(MIN($F143,9))+1)))) | H143: =IF($A143="","",IF(ISNA(MATCH($A143,CALC!$A$6:$A$143,0)),"",IF(INDEX(CALC!$H$6:$H$143,MATCH($A143,CALC!$A$6:$A$143,0))="","",INDEX(CALC!$H$6:$H$143,MATCH($A143,CALC!$A$6:$A$143,0))))) | I143: =IF($E143="","",IF(OR($H143="",$F143=0,$F143=""),$E143,$G143*$E143+(1-$G143)*$H143)) | J143: =IF(OR($A143="",SETTINGS!$B$4="",SETTINGS!$B$4<=1),"",IF(COUNTIFS(HISTORY!$A$6:$A$3005,SETTINGS!$B$4-1,HISTORY!$B$6:$B$3005,$A143)=1,SUMIFS(HISTORY!$C$6:$C$3005,HISTORY!$A$6:$A$3005,SETTINGS!$B$4-1,HISTORY!$B$6:$B$3005,$A143),"")) | K143: =IF($I143="","",IF(ISNUMBER($J143),$J143+MAX(-SETTINGS!$B$12,MIN(SETTINGS!$B$12,$I143-$J143)),$I143)) | O143: =IF($A143="","",IF(ISNUMBER($L143),$L143,IF($K143="","",$K143))) | P143: =IF($A143="","",IF(ISNUMBER($L143),"OVERRIDE","MODEL")) | Q143: =IF($A143="","",SETTINGS!$B$6) | S143: =IF($A143="","",IF(ISNUMBER($R143),$R143,$Q143)) | W143: =IF($A143="","",SUMIFS(CLEAN!$AD$6:$AD$1005,CLEAN!$P$6:$P$1005,$A143)+SUMIFS(CLEAN!$AE$6:$AE$1005,CLEAN!$N$6:$N$1005,$A143))

Sheet QB VALUES
A6: =IF('TEAM RATINGS'!$A6="","",'TEAM RATINGS'!$A6) | B6: =IF('TEAM RATINGS'!$A6="","",'TEAM RATINGS'!$B6) | G6: =IF(OR($D6="",$F6=""),"",$F6-$D6) | M6: =IF($A6="","",IF(OR($G6="",$H6="L",$J6<>SETTINGS!$B$3),"UNCERTAIN","OK"))
A7: =IF('TEAM RATINGS'!$A7="","",'TEAM RATINGS'!$A7) | B7: =IF('TEAM RATINGS'!$A7="","",'TEAM RATINGS'!$B7) | G7: =IF(OR($D7="",$F7=""),"",$F7-$D7) | M7: =IF($A7="","",IF(OR($G7="",$H7="L",$J7<>SETTINGS!$B$3),"UNCERTAIN","OK"))
A8: =IF('TEAM RATINGS'!$A8="","",'TEAM RATINGS'!$A8) | B8: =IF('TEAM RATINGS'!$A8="","",'TEAM RATINGS'!$B8) | G8: =IF(OR($D8="",$F8=""),"",$F8-$D8) | M8: =IF($A8="","",IF(OR($G8="",$H8="L",$J8<>SETTINGS!$B$3),"UNCERTAIN","OK"))
A9: =IF('TEAM RATINGS'!$A9="","",'TEAM RATINGS'!$A9) | B9: =IF('TEAM RATINGS'!$A9="","",'TEAM RATINGS'!$B9) | G9: =IF(OR($D9="",$F9=""),"",$F9-$D9) | M9: =IF($A9="","",IF(OR($G9="",$H9="L",$J9<>SETTINGS!$B$3),"UNCERTAIN","OK"))
A10: =IF('TEAM RATINGS'!$A10="","",'TEAM RATINGS'!$A10) | B10: =IF('TEAM RATINGS'!$A10="","",'TEAM RATINGS'!$B10) | G10: =IF(OR($D10="",$F10=""),"",$F10-$D10) | M10: =IF($A10="","",IF(OR($G10="",$H10="L",$J10<>SETTINGS!$B$3),"UNCERTAIN","OK"))
A11: =IF('TEAM RATINGS'!$A11="","",'TEAM RATINGS'!$A11) | B11: =IF('TEAM RATINGS'!$A11="","",'TEAM RATINGS'!$B11) | G11: =IF(OR($D11="",$F11=""),"",$F11-$D11) | M11: =IF($A11="","",IF(OR($G11="",$H11="L",$J11<>SETTINGS!$B$3),"UNCERTAIN","OK"))
A12: =IF('TEAM RATINGS'!$A12="","",'TEAM RATINGS'!$A12) | B12: =IF('TEAM RATINGS'!$A12="","",'TEAM RATINGS'!$B12) | G12: =IF(OR($D12="",$F12=""),"",$F12-$D12) | M12: =IF($A12="","",IF(OR($G12="",$H12="L",$J12<>SETTINGS!$B$3),"UNCERTAIN","OK"))
A13: =IF('TEAM RATINGS'!$A13="","",'TEAM RATINGS'!$A13) | B13: =IF('TEAM RATINGS'!$A13="","",'TEAM RATINGS'!$B13) | G13: =IF(OR($D13="",$F13=""),"",$F13-$D13) | M13: =IF($A13="","",IF(OR($G13="",$H13="L",$J13<>SETTINGS!$B$3),"UNCERTAIN","OK"))
A14: =IF('TEAM RATINGS'!$A14="","",'TEAM RATINGS'!$A14) | B14: =IF('TEAM RATINGS'!$A14="","",'TEAM RATINGS'!$B14) | G14: =IF(OR($D14="",$F14=""),"",$F14-$D14) | M14: =IF($A14="","",IF(OR($G14="",$H14="L",$J14<>SETTINGS!$B$3),"UNCERTAIN","OK"))
A15: =IF('TEAM RATINGS'!$A15="","",'TEAM RATINGS'!$A15) | B15: =IF('TEAM RATINGS'!$A15="","",'TEAM RATINGS'!$B15) | G15: =IF(OR($D15="",$F15=""),"",$F15-$D15) | M15: =IF($A15="","",IF(OR($G15="",$H15="L",$J15<>SETTINGS!$B$3),"UNCERTAIN","OK"))
A16: =IF('TEAM RATINGS'!$A16="","",'TEAM RATINGS'!$A16) | B16: =IF('TEAM RATINGS'!$A16="","",'TEAM RATINGS'!$B16) | G16: =IF(OR($D16="",$F16=""),"",$F16-$D16) | M16: =IF($A16="","",IF(OR($G16="",$H16="L",$J16<>SETTINGS!$B$3),"UNCERTAIN","OK"))
A17: =IF('TEAM RATINGS'!$A17="","",'TEAM RATINGS'!$A17) | B17: =IF('TEAM RATINGS'!$A17="","",'TEAM RATINGS'!$B17) | G17: =IF(OR($D17="",$F17=""),"",$F17-$D17) | M17: =IF($A17="","",IF(OR($G17="",$H17="L",$J17<>SETTINGS!$B$3),"UNCERTAIN","OK"))
... A63: =IF('TEAM RATINGS'!$A63="","",'TEAM RATINGS'!$A63) | B63: =IF('TEAM RATINGS'!$A63="","",'TEAM RATINGS'!$B63) | G63: =IF(OR($D63="",$F63=""),"",$F63-$D63) | M63: =IF($A63="","",IF(OR($G63="",$H63="L",$J63<>SETTINGS!$B$3),"UNCERTAIN","OK"))
A64: =IF('TEAM RATINGS'!$A64="","",'TEAM RATINGS'!$A64) | B64: =IF('TEAM RATINGS'!$A64="","",'TEAM RATINGS'!$B64) | C64: TEST ONLY — NOT REAL DATA: Test Baseline QB | D64: 0 | E64: TEST ONLY — NOT REAL DATA: Test Active QB | F64: 0 | G64: =IF(OR($D64="",$F64=""),"",$F64-$D64) | H64: M | I64: TEST ONLY — NOT REAL DATA | J64: 2026 | K64: 46266 | L64: TEST ONLY — NOT REAL DATA: temporarily resolved for DATA INCOMPLETE isolation | M64: =IF($A64="","",IF(OR($G64="",$H64="L",$J64<>SETTINGS!$B$3),"UNCERTAIN","OK"))
A65: =IF('TEAM RATINGS'!$A65="","",'TEAM RATINGS'!$A65) | B65: =IF('TEAM RATINGS'!$A65="","",'TEAM RATINGS'!$B65) | G65: =IF(OR($D65="",$F65=""),"",$F65-$D65) | M65: =IF($A65="","",IF(OR($G65="",$H65="L",$J65<>SETTINGS!$B$3),"UNCERTAIN","OK"))
A66: =IF('TEAM RATINGS'!$A66="","",'TEAM RATINGS'!$A66) | B66: =IF('TEAM RATINGS'!$A66="","",'TEAM RATINGS'!$B66) | G66: =IF(OR($D66="",$F66=""),"",$F66-$D66) | M66: =IF($A66="","",IF(OR($G66="",$H66="L",$J66<>SETTINGS!$B$3),"UNCERTAIN","OK"))
A67: =IF('TEAM RATINGS'!$A67="","",'TEAM RATINGS'!$A67) | B67: =IF('TEAM RATINGS'!$A67="","",'TEAM RATINGS'!$B67) | G67: =IF(OR($D67="",$F67=""),"",$F67-$D67) | M67: =IF($A67="","",IF(OR($G67="",$H67="L",$J67<>SETTINGS!$B$3),"UNCERTAIN","OK"))
A68: =IF('TEAM RATINGS'!$A68="","",'TEAM RATINGS'!$A68) | B68: =IF('TEAM RATINGS'!$A68="","",'TEAM RATINGS'!$B68) | G68: =IF(OR($D68="",$F68=""),"",$F68-$D68) | M68: =IF($A68="","",IF(OR($G68="",$H68="L",$J68<>SETTINGS!$B$3),"UNCERTAIN","OK"))
A69: =IF('TEAM RATINGS'!$A69="","",'TEAM RATINGS'!$A69) | B69: =IF('TEAM RATINGS'!$A69="","",'TEAM RATINGS'!$B69) | G69: =IF(OR($D69="",$F69=""),"",$F69-$D69) | M69: =IF($A69="","",IF(OR($G69="",$H69="L",$J69<>SETTINGS!$B$3),"UNCERTAIN","OK"))
A70: =IF('TEAM RATINGS'!$A70="","",'TEAM RATINGS'!$A70) | B70: =IF('TEAM RATINGS'!$A70="","",'TEAM RATINGS'!$B70) | C70: TEST ONLY — NOT REAL DATA: Test Baseline QB | D70: 0 | E70: TEST ONLY — NOT REAL DATA: Test Active QB | F70: 0 | G70: =IF(OR($D70="",$F70=""),"",$F70-$D70) | H70: M | I70: TEST ONLY — NOT REAL DATA | J70: 2026 | K70: 46266 | L70: TEST ONLY — NOT REAL DATA: temporarily resolved for DATA INCOMPLETE isolation | M70: =IF($A70="","",IF(OR($G70="",$H70="L",$J70<>SETTINGS!$B$3),"UNCERTAIN","OK"))
A71: =IF('TEAM RATINGS'!$A71="","",'TEAM RATINGS'!$A71) | B71: =IF('TEAM RATINGS'!$A71="","",'TEAM RATINGS'!$B71) | G71: =IF(OR($D71="",$F71=""),"",$F71-$D71) | M71: =IF($A71="","",IF(OR($G71="",$H71="L",$J71<>SETTINGS!$B$3),"UNCERTAIN","OK"))
A72: =IF('TEAM RATINGS'!$A72="","",'TEAM RATINGS'!$A72) | B72: =IF('TEAM RATINGS'!$A72="","",'TEAM RATINGS'!$B72) | G72: =IF(OR($D72="",$F72=""),"",$F72-$D72) | M72: =IF($A72="","",IF(OR($G72="",$H72="L",$J72<>SETTINGS!$B$3),"UNCERTAIN","OK"))
A73: =IF('TEAM RATINGS'!$A73="","",'TEAM RATINGS'!$A73) | B73: =IF('TEAM RATINGS'!$A73="","",'TEAM RATINGS'!$B73) | G73: =IF(OR($D73="",$F73=""),"",$F73-$D73) | M73: =IF($A73="","",IF(OR($G73="",$H73="L",$J73<>SETTINGS!$B$3),"UNCERTAIN","OK"))
A74: =IF('TEAM RATINGS'!$A74="","",'TEAM RATINGS'!$A74) | B74: =IF('TEAM RATINGS'!$A74="","",'TEAM RATINGS'!$B74) | G74: =IF(OR($D74="",$F74=""),"",$F74-$D74) | M74: =IF($A74="","",IF(OR($G74="",$H74="L",$J74<>SETTINGS!$B$3),"UNCERTAIN","OK"))
A75: =IF('TEAM RATINGS'!$A75="","",'TEAM RATINGS'!$A75) | B75: =IF('TEAM RATINGS'!$A75="","",'TEAM RATINGS'!$B75) | G75: =IF(OR($D75="",$F75=""),"",$F75-$D75) | M75: =IF($A75="","",IF(OR($G75="",$H75="L",$J75<>SETTINGS!$B$3),"UNCERTAIN","OK"))
A76: =IF('TEAM RATINGS'!$A76="","",'TEAM RATINGS'!$A76) | B76: =IF('TEAM RATINGS'!$A76="","",'TEAM RATINGS'!$B76) | G76: =IF(OR($D76="",$F76=""),"",$F76-$D76) | M76: =IF($A76="","",IF(OR($G76="",$H76="L",$J76<>SETTINGS!$B$3),"UNCERTAIN","OK"))
A77: =IF('TEAM RATINGS'!$A77="","",'TEAM RATINGS'!$A77) | B77: =IF('TEAM RATINGS'!$A77="","",'TEAM RATINGS'!$B77) | G77: =IF(OR($D77="",$F77=""),"",$F77-$D77) | M77: =IF($A77="","",IF(OR($G77="",$H77="L",$J77<>SETTINGS!$B$3),"UNCERTAIN","OK"))
A78: =IF('TEAM RATINGS'!$A78="","",'TEAM RATINGS'!$A78) | B78: =IF('TEAM RATINGS'!$A78="","",'TEAM RATINGS'!$B78) | G78: =IF(OR($D78="",$F78=""),"",$F78-$D78) | M78: =IF($A78="","",IF(OR($G78="",$H78="L",$J78<>SETTINGS!$B$3),"UNCERTAIN","OK"))
A79: =IF('TEAM RATINGS'!$A79="","",'TEAM RATINGS'!$A79) | B79: =IF('TEAM RATINGS'!$A79="","",'TEAM RATINGS'!$B79) | G79: =IF(OR($D79="",$F79=""),"",$F79-$D79) | M79: =IF($A79="","",IF(OR($G79="",$H79="L",$J79<>SETTINGS!$B$3),"UNCERTAIN","OK"))
A80: =IF('TEAM RATINGS'!$A80="","",'TEAM RATINGS'!$A80) | B80: =IF('TEAM RATINGS'!$A80="","",'TEAM RATINGS'!$B80) | G80: =IF(OR($D80="",$F80=""),"",$F80-$D80) | M80: =IF($A80="","",IF(OR($G80="",$H80="L",$J80<>SETTINGS!$B$3),"UNCERTAIN","OK"))
A81: =IF('TEAM RATINGS'!$A81="","",'TEAM RATINGS'!$A81) | B81: =IF('TEAM RATINGS'!$A81="","",'TEAM RATINGS'!$B81) | G81: =IF(OR($D81="",$F81=""),"",$F81-$D81) | M81: =IF($A81="","",IF(OR($G81="",$H81="L",$J81<>SETTINGS!$B$3),"UNCERTAIN","OK"))
A82: =IF('TEAM RATINGS'!$A82="","",'TEAM RATINGS'!$A82) | B82: =IF('TEAM RATINGS'!$A82="","",'TEAM RATINGS'!$B82) | G82: =IF(OR($D82="",$F82=""),"",$F82-$D82) | M82: =IF($A82="","",IF(OR($G82="",$H82="L",$J82<>SETTINGS!$B$3),"UNCERTAIN","OK"))
... A143: =IF('TEAM RATINGS'!$A143="","",'TEAM RATINGS'!$A143) | B143: =IF('TEAM RATINGS'!$A143="","",'TEAM RATINGS'!$B143) | G143: =IF(OR($D143="",$F143=""),"",$F143-$D143) | M143: =IF($A143="","",IF(OR($G143="",$H143="L",$J143<>SETTINGS!$B$3),"UNCERTAIN","OK"))

Sheet IMPORT SCHEDULE
A6: 401856766 | B6: 2026 | C6: 0 | D6: 46263 | E6: TRUE | F6: North Carolina Tar Heels | G6: Atlantic Coast Conference | H6: TCU Horned Frogs | I6: Big 12 Conference | L6: FALSE | M6: Aviva Stadium | N6: ESPN event note: Aer Lingus College Football Classic | ESPN source: season_type=2 (regular-season), week=1. Normalized to project Week 0 (opening slate before the 2026-09-03 Week 1 kickoff).
A8: 401858202 | B8: 2026 | D8: 46263 | E8: FALSE | F8: NC State Wolfpack | G8: Atlantic Coast Conference | H8: Virginia Cavaliers | I8: Atlantic Coast Conference | L8: FALSE | M8: Scott Stadium | N8: ESPN source: season_type=2 (regular-season), week=1. Normalized to project Week 0 (opening slate before the 2026-09-03 Week 1 kickoff).
A9: 401864494 | B9: 2026 | C9: 0 | D9: 46263 | E9: FALSE | F9: San José State Spartans | G9: Mountain West Conference | H9: USC Trojans | I9: Big Ten Conference | L9: FALSE | M9: Los Angeles Memorial Coliseum | N9: ESPN source: season_type=2 (regular-season), week=1. Normalized to project Week 0 (opening slate before the 2026-09-03 Week 1 kickoff).
A10: 401864570 | B10: 2026 | C10: 0 | D10: 46263 | E10: FALSE | F10: New Mexico State Aggies | G10: Conference USA | H10: Florida State Seminoles | I10: Atlantic Coast Conference | L10: FALSE | M10: Doak Campbell Stadium | N10: ESPN source: season_type=2 (regular-season), week=1. Normalized to project Week 0 (opening slate before the 2026-09-03 Week 1 kickoff).
A11: 401864577 | B11: 2026 | C11: 0 | D11: 46263 | E11: FALSE | F11: Jacksonville State Gamecocks | G11: Conference USA | H11: North Dakota State Bison | I11: Mountain West Conference | L11: FALSE | M11: Fargodome | N11: North Dakota State: ESPN structured conferenceId already matches approved 2026 assignment (Mountain West Conference). | ESPN source: season_type=2 (regular-season), week=1. Normalized to project Week 0 (opening slate before the 2026-09-03 Week 1 kickoff).
A14: 401856767 | B14: 2026 | C14: 1 | D14: 46268 | E14: FALSE | F14: Bethune-Cookman Wildcats | G14: Southwestern Athletic Conference | H14: UCF Knights | I14: Big 12 Conference | L14: FALSE | M14: Acrisure Bounce House
A15: 401858204 | B15: 2026 | C15: 1 | D15: 46268 | E15: FALSE | F15: Akron Zips | G15: Mid-American Conference | H15: Wake Forest Demon Deacons | I15: Atlantic Coast Conference | L15: FALSE | M15: Allegacy Federal Credit Union Stadium

Sheet CLEAN
